[2022-06-03 15:41:58,151] {processor.py:153} INFO - Started process (PID=2296) to work on /opt/airflow/dags/process_users_dag.py
[2022-06-03 15:41:58,151] {processor.py:641} INFO - Processing file /opt/airflow/dags/process_users_dag.py for tasks to queue
[2022-06-03 15:41:58,152] {logging_mixin.py:115} INFO - [2022-06-03 15:41:58,152] {dagbag.py:507} INFO - Filling up the DagBag from /opt/airflow/dags/process_users_dag.py
[2022-06-03 15:41:58,155] {logging_mixin.py:115} INFO - [2022-06-03 15:41:58,154] {dagbag.py:320} ERROR - Failed to import: /opt/airflow/dags/process_users_dag.py
Traceback (most recent call last):
  File "/home/airflow/.local/lib/python3.7/site-packages/airflow/models/dagbag.py", line 317, in parse
    loader.exec_module(new_module)
  File "<frozen importlib._bootstrap_external>", line 724, in exec_module
  File "<frozen importlib._bootstrap_external>", line 860, in get_code
  File "<frozen importlib._bootstrap_external>", line 791, in source_to_code
  File "<frozen importlib._bootstrap>", line 219, in _call_with_frames_removed
  File "/opt/airflow/dags/process_users_dag.py", line 3
    from pendulum immport datetime
                        ^
SyntaxError: invalid syntax
[2022-06-03 15:41:58,156] {processor.py:653} WARNING - No viable dags retrieved from /opt/airflow/dags/process_users_dag.py
[2022-06-03 15:41:58,182] {processor.py:161} INFO - Processing /opt/airflow/dags/process_users_dag.py took 0.037 seconds
[2022-06-03 15:42:28,262] {processor.py:153} INFO - Started process (PID=2317) to work on /opt/airflow/dags/process_users_dag.py
[2022-06-03 15:42:28,268] {processor.py:641} INFO - Processing file /opt/airflow/dags/process_users_dag.py for tasks to queue
[2022-06-03 15:42:28,269] {logging_mixin.py:115} INFO - [2022-06-03 15:42:28,268] {dagbag.py:507} INFO - Filling up the DagBag from /opt/airflow/dags/process_users_dag.py
[2022-06-03 15:42:28,271] {logging_mixin.py:115} INFO - [2022-06-03 15:42:28,270] {dagbag.py:320} ERROR - Failed to import: /opt/airflow/dags/process_users_dag.py
Traceback (most recent call last):
  File "/home/airflow/.local/lib/python3.7/site-packages/airflow/models/dagbag.py", line 317, in parse
    loader.exec_module(new_module)
  File "<frozen importlib._bootstrap_external>", line 724, in exec_module
  File "<frozen importlib._bootstrap_external>", line 860, in get_code
  File "<frozen importlib._bootstrap_external>", line 791, in source_to_code
  File "<frozen importlib._bootstrap>", line 219, in _call_with_frames_removed
  File "/opt/airflow/dags/process_users_dag.py", line 3
    from pendulum immport datetime
                        ^
SyntaxError: invalid syntax
[2022-06-03 15:42:28,271] {processor.py:653} WARNING - No viable dags retrieved from /opt/airflow/dags/process_users_dag.py
[2022-06-03 15:42:28,301] {processor.py:161} INFO - Processing /opt/airflow/dags/process_users_dag.py took 0.043 seconds
[2022-06-03 15:42:58,378] {processor.py:153} INFO - Started process (PID=2347) to work on /opt/airflow/dags/process_users_dag.py
[2022-06-03 15:42:58,385] {processor.py:641} INFO - Processing file /opt/airflow/dags/process_users_dag.py for tasks to queue
[2022-06-03 15:42:58,385] {logging_mixin.py:115} INFO - [2022-06-03 15:42:58,385] {dagbag.py:507} INFO - Filling up the DagBag from /opt/airflow/dags/process_users_dag.py
[2022-06-03 15:42:58,388] {logging_mixin.py:115} INFO - [2022-06-03 15:42:58,387] {dagbag.py:320} ERROR - Failed to import: /opt/airflow/dags/process_users_dag.py
Traceback (most recent call last):
  File "/home/airflow/.local/lib/python3.7/site-packages/airflow/models/dagbag.py", line 317, in parse
    loader.exec_module(new_module)
  File "<frozen importlib._bootstrap_external>", line 724, in exec_module
  File "<frozen importlib._bootstrap_external>", line 860, in get_code
  File "<frozen importlib._bootstrap_external>", line 791, in source_to_code
  File "<frozen importlib._bootstrap>", line 219, in _call_with_frames_removed
  File "/opt/airflow/dags/process_users_dag.py", line 3
    from pendulum immport datetime
                        ^
SyntaxError: invalid syntax
[2022-06-03 15:42:58,388] {processor.py:653} WARNING - No viable dags retrieved from /opt/airflow/dags/process_users_dag.py
[2022-06-03 15:42:58,422] {processor.py:161} INFO - Processing /opt/airflow/dags/process_users_dag.py took 0.049 seconds
[2022-06-03 15:43:28,513] {processor.py:153} INFO - Started process (PID=2367) to work on /opt/airflow/dags/process_users_dag.py
[2022-06-03 15:43:28,515] {processor.py:641} INFO - Processing file /opt/airflow/dags/process_users_dag.py for tasks to queue
[2022-06-03 15:43:28,516] {logging_mixin.py:115} INFO - [2022-06-03 15:43:28,516] {dagbag.py:507} INFO - Filling up the DagBag from /opt/airflow/dags/process_users_dag.py
[2022-06-03 15:43:28,518] {logging_mixin.py:115} INFO - [2022-06-03 15:43:28,517] {dagbag.py:320} ERROR - Failed to import: /opt/airflow/dags/process_users_dag.py
Traceback (most recent call last):
  File "/home/airflow/.local/lib/python3.7/site-packages/airflow/models/dagbag.py", line 317, in parse
    loader.exec_module(new_module)
  File "<frozen importlib._bootstrap_external>", line 724, in exec_module
  File "<frozen importlib._bootstrap_external>", line 860, in get_code
  File "<frozen importlib._bootstrap_external>", line 791, in source_to_code
  File "<frozen importlib._bootstrap>", line 219, in _call_with_frames_removed
  File "/opt/airflow/dags/process_users_dag.py", line 3
    from pendulum immport datetime
                        ^
SyntaxError: invalid syntax
[2022-06-03 15:43:28,518] {processor.py:653} WARNING - No viable dags retrieved from /opt/airflow/dags/process_users_dag.py
[2022-06-03 15:43:28,545] {processor.py:161} INFO - Processing /opt/airflow/dags/process_users_dag.py took 0.037 seconds
[2022-06-03 15:43:58,625] {processor.py:153} INFO - Started process (PID=2387) to work on /opt/airflow/dags/process_users_dag.py
[2022-06-03 15:43:58,626] {processor.py:641} INFO - Processing file /opt/airflow/dags/process_users_dag.py for tasks to queue
[2022-06-03 15:43:58,627] {logging_mixin.py:115} INFO - [2022-06-03 15:43:58,627] {dagbag.py:507} INFO - Filling up the DagBag from /opt/airflow/dags/process_users_dag.py
[2022-06-03 15:43:58,629] {logging_mixin.py:115} INFO - [2022-06-03 15:43:58,628] {dagbag.py:320} ERROR - Failed to import: /opt/airflow/dags/process_users_dag.py
Traceback (most recent call last):
  File "/home/airflow/.local/lib/python3.7/site-packages/airflow/models/dagbag.py", line 317, in parse
    loader.exec_module(new_module)
  File "<frozen importlib._bootstrap_external>", line 724, in exec_module
  File "<frozen importlib._bootstrap_external>", line 860, in get_code
  File "<frozen importlib._bootstrap_external>", line 791, in source_to_code
  File "<frozen importlib._bootstrap>", line 219, in _call_with_frames_removed
  File "/opt/airflow/dags/process_users_dag.py", line 3
    from pendulum immport datetime
                        ^
SyntaxError: invalid syntax
[2022-06-03 15:43:58,629] {processor.py:653} WARNING - No viable dags retrieved from /opt/airflow/dags/process_users_dag.py
[2022-06-03 15:43:58,662] {processor.py:161} INFO - Processing /opt/airflow/dags/process_users_dag.py took 0.040 seconds
[2022-06-03 15:44:28,742] {processor.py:153} INFO - Started process (PID=2417) to work on /opt/airflow/dags/process_users_dag.py
[2022-06-03 15:44:28,743] {processor.py:641} INFO - Processing file /opt/airflow/dags/process_users_dag.py for tasks to queue
[2022-06-03 15:44:28,745] {logging_mixin.py:115} INFO - [2022-06-03 15:44:28,744] {dagbag.py:507} INFO - Filling up the DagBag from /opt/airflow/dags/process_users_dag.py
[2022-06-03 15:44:28,749] {logging_mixin.py:115} INFO - [2022-06-03 15:44:28,747] {dagbag.py:320} ERROR - Failed to import: /opt/airflow/dags/process_users_dag.py
Traceback (most recent call last):
  File "/home/airflow/.local/lib/python3.7/site-packages/airflow/models/dagbag.py", line 317, in parse
    loader.exec_module(new_module)
  File "<frozen importlib._bootstrap_external>", line 724, in exec_module
  File "<frozen importlib._bootstrap_external>", line 860, in get_code
  File "<frozen importlib._bootstrap_external>", line 791, in source_to_code
  File "<frozen importlib._bootstrap>", line 219, in _call_with_frames_removed
  File "/opt/airflow/dags/process_users_dag.py", line 3
    from pendulum immport datetime
                        ^
SyntaxError: invalid syntax
[2022-06-03 15:44:28,750] {processor.py:653} WARNING - No viable dags retrieved from /opt/airflow/dags/process_users_dag.py
[2022-06-03 15:44:28,780] {processor.py:161} INFO - Processing /opt/airflow/dags/process_users_dag.py took 0.044 seconds
[2022-06-03 15:44:58,865] {processor.py:153} INFO - Started process (PID=2437) to work on /opt/airflow/dags/process_users_dag.py
[2022-06-03 15:44:58,872] {processor.py:641} INFO - Processing file /opt/airflow/dags/process_users_dag.py for tasks to queue
[2022-06-03 15:44:58,875] {logging_mixin.py:115} INFO - [2022-06-03 15:44:58,875] {dagbag.py:507} INFO - Filling up the DagBag from /opt/airflow/dags/process_users_dag.py
[2022-06-03 15:44:58,881] {logging_mixin.py:115} INFO - [2022-06-03 15:44:58,879] {dagbag.py:320} ERROR - Failed to import: /opt/airflow/dags/process_users_dag.py
Traceback (most recent call last):
  File "/home/airflow/.local/lib/python3.7/site-packages/airflow/models/dagbag.py", line 317, in parse
    loader.exec_module(new_module)
  File "<frozen importlib._bootstrap_external>", line 724, in exec_module
  File "<frozen importlib._bootstrap_external>", line 860, in get_code
  File "<frozen importlib._bootstrap_external>", line 791, in source_to_code
  File "<frozen importlib._bootstrap>", line 219, in _call_with_frames_removed
  File "/opt/airflow/dags/process_users_dag.py", line 3
    from pendulum immport datetime
                        ^
SyntaxError: invalid syntax
[2022-06-03 15:44:58,881] {processor.py:653} WARNING - No viable dags retrieved from /opt/airflow/dags/process_users_dag.py
[2022-06-03 15:44:58,922] {processor.py:161} INFO - Processing /opt/airflow/dags/process_users_dag.py took 0.063 seconds
[2022-06-03 15:45:29,005] {processor.py:153} INFO - Started process (PID=2467) to work on /opt/airflow/dags/process_users_dag.py
[2022-06-03 15:45:29,006] {processor.py:641} INFO - Processing file /opt/airflow/dags/process_users_dag.py for tasks to queue
[2022-06-03 15:45:29,007] {logging_mixin.py:115} INFO - [2022-06-03 15:45:29,007] {dagbag.py:507} INFO - Filling up the DagBag from /opt/airflow/dags/process_users_dag.py
[2022-06-03 15:45:29,009] {logging_mixin.py:115} INFO - [2022-06-03 15:45:29,008] {dagbag.py:320} ERROR - Failed to import: /opt/airflow/dags/process_users_dag.py
Traceback (most recent call last):
  File "/home/airflow/.local/lib/python3.7/site-packages/airflow/models/dagbag.py", line 317, in parse
    loader.exec_module(new_module)
  File "<frozen importlib._bootstrap_external>", line 724, in exec_module
  File "<frozen importlib._bootstrap_external>", line 860, in get_code
  File "<frozen importlib._bootstrap_external>", line 791, in source_to_code
  File "<frozen importlib._bootstrap>", line 219, in _call_with_frames_removed
  File "/opt/airflow/dags/process_users_dag.py", line 3
    from pendulum immport datetime
                        ^
SyntaxError: invalid syntax
[2022-06-03 15:45:29,010] {processor.py:653} WARNING - No viable dags retrieved from /opt/airflow/dags/process_users_dag.py
[2022-06-03 15:45:29,040] {processor.py:161} INFO - Processing /opt/airflow/dags/process_users_dag.py took 0.039 seconds
[2022-06-03 15:45:41,051] {processor.py:153} INFO - Started process (PID=2477) to work on /opt/airflow/dags/process_users_dag.py
[2022-06-03 15:45:41,052] {processor.py:641} INFO - Processing file /opt/airflow/dags/process_users_dag.py for tasks to queue
[2022-06-03 15:45:41,055] {logging_mixin.py:115} INFO - [2022-06-03 15:45:41,055] {dagbag.py:507} INFO - Filling up the DagBag from /opt/airflow/dags/process_users_dag.py
[2022-06-03 15:45:41,060] {logging_mixin.py:115} INFO - [2022-06-03 15:45:41,058] {dagbag.py:320} ERROR - Failed to import: /opt/airflow/dags/process_users_dag.py
Traceback (most recent call last):
  File "/home/airflow/.local/lib/python3.7/site-packages/airflow/models/dagbag.py", line 317, in parse
    loader.exec_module(new_module)
  File "<frozen importlib._bootstrap_external>", line 724, in exec_module
  File "<frozen importlib._bootstrap_external>", line 860, in get_code
  File "<frozen importlib._bootstrap_external>", line 791, in source_to_code
  File "<frozen importlib._bootstrap>", line 219, in _call_with_frames_removed
  File "/opt/airflow/dags/process_users_dag.py", line 9
    USERS_JSON_FILENAME =
                         ^
SyntaxError: invalid syntax
[2022-06-03 15:45:41,060] {processor.py:653} WARNING - No viable dags retrieved from /opt/airflow/dags/process_users_dag.py
[2022-06-03 15:45:41,113] {processor.py:161} INFO - Processing /opt/airflow/dags/process_users_dag.py took 0.069 seconds
[2022-06-03 15:46:11,223] {processor.py:153} INFO - Started process (PID=2497) to work on /opt/airflow/dags/process_users_dag.py
[2022-06-03 15:46:11,231] {processor.py:641} INFO - Processing file /opt/airflow/dags/process_users_dag.py for tasks to queue
[2022-06-03 15:46:11,233] {logging_mixin.py:115} INFO - [2022-06-03 15:46:11,232] {dagbag.py:507} INFO - Filling up the DagBag from /opt/airflow/dags/process_users_dag.py
[2022-06-03 15:46:11,237] {logging_mixin.py:115} INFO - [2022-06-03 15:46:11,235] {dagbag.py:320} ERROR - Failed to import: /opt/airflow/dags/process_users_dag.py
Traceback (most recent call last):
  File "/home/airflow/.local/lib/python3.7/site-packages/airflow/models/dagbag.py", line 317, in parse
    loader.exec_module(new_module)
  File "<frozen importlib._bootstrap_external>", line 724, in exec_module
  File "<frozen importlib._bootstrap_external>", line 860, in get_code
  File "<frozen importlib._bootstrap_external>", line 791, in source_to_code
  File "<frozen importlib._bootstrap>", line 219, in _call_with_frames_removed
  File "/opt/airflow/dags/process_users_dag.py", line 9
    USERS_JSON_FILENAME =
                         ^
SyntaxError: invalid syntax
[2022-06-03 15:46:11,238] {processor.py:653} WARNING - No viable dags retrieved from /opt/airflow/dags/process_users_dag.py
[2022-06-03 15:46:11,290] {processor.py:161} INFO - Processing /opt/airflow/dags/process_users_dag.py took 0.074 seconds
[2022-06-03 15:46:41,409] {processor.py:153} INFO - Started process (PID=2516) to work on /opt/airflow/dags/process_users_dag.py
[2022-06-03 15:46:41,417] {processor.py:641} INFO - Processing file /opt/airflow/dags/process_users_dag.py for tasks to queue
[2022-06-03 15:46:41,419] {logging_mixin.py:115} INFO - [2022-06-03 15:46:41,418] {dagbag.py:507} INFO - Filling up the DagBag from /opt/airflow/dags/process_users_dag.py
[2022-06-03 15:46:41,426] {logging_mixin.py:115} INFO - [2022-06-03 15:46:41,423] {dagbag.py:320} ERROR - Failed to import: /opt/airflow/dags/process_users_dag.py
Traceback (most recent call last):
  File "/home/airflow/.local/lib/python3.7/site-packages/airflow/models/dagbag.py", line 317, in parse
    loader.exec_module(new_module)
  File "<frozen importlib._bootstrap_external>", line 724, in exec_module
  File "<frozen importlib._bootstrap_external>", line 860, in get_code
  File "<frozen importlib._bootstrap_external>", line 791, in source_to_code
  File "<frozen importlib._bootstrap>", line 219, in _call_with_frames_removed
  File "/opt/airflow/dags/process_users_dag.py", line 9
    USERS_JSON_FILENAME =
                         ^
SyntaxError: invalid syntax
[2022-06-03 15:46:41,427] {processor.py:653} WARNING - No viable dags retrieved from /opt/airflow/dags/process_users_dag.py
[2022-06-03 15:46:41,500] {processor.py:161} INFO - Processing /opt/airflow/dags/process_users_dag.py took 0.104 seconds
[2022-06-03 15:47:11,619] {processor.py:153} INFO - Started process (PID=2544) to work on /opt/airflow/dags/process_users_dag.py
[2022-06-03 15:47:11,620] {processor.py:641} INFO - Processing file /opt/airflow/dags/process_users_dag.py for tasks to queue
[2022-06-03 15:47:11,620] {logging_mixin.py:115} INFO - [2022-06-03 15:47:11,620] {dagbag.py:507} INFO - Filling up the DagBag from /opt/airflow/dags/process_users_dag.py
[2022-06-03 15:47:11,622] {logging_mixin.py:115} INFO - [2022-06-03 15:47:11,622] {dagbag.py:320} ERROR - Failed to import: /opt/airflow/dags/process_users_dag.py
Traceback (most recent call last):
  File "/home/airflow/.local/lib/python3.7/site-packages/airflow/models/dagbag.py", line 317, in parse
    loader.exec_module(new_module)
  File "<frozen importlib._bootstrap_external>", line 724, in exec_module
  File "<frozen importlib._bootstrap_external>", line 860, in get_code
  File "<frozen importlib._bootstrap_external>", line 791, in source_to_code
  File "<frozen importlib._bootstrap>", line 219, in _call_with_frames_removed
  File "/opt/airflow/dags/process_users_dag.py", line 9
    USERS_JSON_FILENAME =
                         ^
SyntaxError: invalid syntax
[2022-06-03 15:47:11,623] {processor.py:653} WARNING - No viable dags retrieved from /opt/airflow/dags/process_users_dag.py
[2022-06-03 15:47:11,648] {processor.py:161} INFO - Processing /opt/airflow/dags/process_users_dag.py took 0.032 seconds
[2022-06-03 15:47:41,762] {processor.py:153} INFO - Started process (PID=2563) to work on /opt/airflow/dags/process_users_dag.py
[2022-06-03 15:47:41,763] {processor.py:641} INFO - Processing file /opt/airflow/dags/process_users_dag.py for tasks to queue
[2022-06-03 15:47:41,765] {logging_mixin.py:115} INFO - [2022-06-03 15:47:41,764] {dagbag.py:507} INFO - Filling up the DagBag from /opt/airflow/dags/process_users_dag.py
[2022-06-03 15:47:41,769] {logging_mixin.py:115} INFO - [2022-06-03 15:47:41,767] {dagbag.py:320} ERROR - Failed to import: /opt/airflow/dags/process_users_dag.py
Traceback (most recent call last):
  File "/home/airflow/.local/lib/python3.7/site-packages/airflow/models/dagbag.py", line 317, in parse
    loader.exec_module(new_module)
  File "<frozen importlib._bootstrap_external>", line 724, in exec_module
  File "<frozen importlib._bootstrap_external>", line 860, in get_code
  File "<frozen importlib._bootstrap_external>", line 791, in source_to_code
  File "<frozen importlib._bootstrap>", line 219, in _call_with_frames_removed
  File "/opt/airflow/dags/process_users_dag.py", line 9
    USERS_JSON_FILENAME =
                         ^
SyntaxError: invalid syntax
[2022-06-03 15:47:41,770] {processor.py:653} WARNING - No viable dags retrieved from /opt/airflow/dags/process_users_dag.py
[2022-06-03 15:47:41,801] {processor.py:161} INFO - Processing /opt/airflow/dags/process_users_dag.py took 0.049 seconds
[2022-06-03 15:48:11,885] {processor.py:153} INFO - Started process (PID=2583) to work on /opt/airflow/dags/process_users_dag.py
[2022-06-03 15:48:11,885] {processor.py:641} INFO - Processing file /opt/airflow/dags/process_users_dag.py for tasks to queue
[2022-06-03 15:48:11,886] {logging_mixin.py:115} INFO - [2022-06-03 15:48:11,886] {dagbag.py:507} INFO - Filling up the DagBag from /opt/airflow/dags/process_users_dag.py
[2022-06-03 15:48:11,888] {logging_mixin.py:115} INFO - [2022-06-03 15:48:11,887] {dagbag.py:320} ERROR - Failed to import: /opt/airflow/dags/process_users_dag.py
Traceback (most recent call last):
  File "/home/airflow/.local/lib/python3.7/site-packages/airflow/models/dagbag.py", line 317, in parse
    loader.exec_module(new_module)
  File "<frozen importlib._bootstrap_external>", line 724, in exec_module
  File "<frozen importlib._bootstrap_external>", line 860, in get_code
  File "<frozen importlib._bootstrap_external>", line 791, in source_to_code
  File "<frozen importlib._bootstrap>", line 219, in _call_with_frames_removed
  File "/opt/airflow/dags/process_users_dag.py", line 9
    USERS_JSON_FILENAME =
                         ^
SyntaxError: invalid syntax
[2022-06-03 15:48:11,889] {processor.py:653} WARNING - No viable dags retrieved from /opt/airflow/dags/process_users_dag.py
[2022-06-03 15:48:11,927] {processor.py:161} INFO - Processing /opt/airflow/dags/process_users_dag.py took 0.046 seconds
[2022-06-03 15:48:42,030] {processor.py:153} INFO - Started process (PID=2612) to work on /opt/airflow/dags/process_users_dag.py
[2022-06-03 15:48:42,031] {processor.py:641} INFO - Processing file /opt/airflow/dags/process_users_dag.py for tasks to queue
[2022-06-03 15:48:42,032] {logging_mixin.py:115} INFO - [2022-06-03 15:48:42,032] {dagbag.py:507} INFO - Filling up the DagBag from /opt/airflow/dags/process_users_dag.py
[2022-06-03 15:48:42,034] {logging_mixin.py:115} INFO - [2022-06-03 15:48:42,033] {dagbag.py:320} ERROR - Failed to import: /opt/airflow/dags/process_users_dag.py
Traceback (most recent call last):
  File "/home/airflow/.local/lib/python3.7/site-packages/airflow/models/dagbag.py", line 317, in parse
    loader.exec_module(new_module)
  File "<frozen importlib._bootstrap_external>", line 724, in exec_module
  File "<frozen importlib._bootstrap_external>", line 860, in get_code
  File "<frozen importlib._bootstrap_external>", line 791, in source_to_code
  File "<frozen importlib._bootstrap>", line 219, in _call_with_frames_removed
  File "/opt/airflow/dags/process_users_dag.py", line 9
    USERS_JSON_FILENAME =
                         ^
SyntaxError: invalid syntax
[2022-06-03 15:48:42,034] {processor.py:653} WARNING - No viable dags retrieved from /opt/airflow/dags/process_users_dag.py
[2022-06-03 15:48:42,063] {processor.py:161} INFO - Processing /opt/airflow/dags/process_users_dag.py took 0.036 seconds
[2022-06-03 15:49:12,177] {processor.py:153} INFO - Started process (PID=2632) to work on /opt/airflow/dags/process_users_dag.py
[2022-06-03 15:49:12,178] {processor.py:641} INFO - Processing file /opt/airflow/dags/process_users_dag.py for tasks to queue
[2022-06-03 15:49:12,179] {logging_mixin.py:115} INFO - [2022-06-03 15:49:12,179] {dagbag.py:507} INFO - Filling up the DagBag from /opt/airflow/dags/process_users_dag.py
[2022-06-03 15:49:12,183] {logging_mixin.py:115} INFO - [2022-06-03 15:49:12,182] {dagbag.py:320} ERROR - Failed to import: /opt/airflow/dags/process_users_dag.py
Traceback (most recent call last):
  File "/home/airflow/.local/lib/python3.7/site-packages/airflow/models/dagbag.py", line 317, in parse
    loader.exec_module(new_module)
  File "<frozen importlib._bootstrap_external>", line 724, in exec_module
  File "<frozen importlib._bootstrap_external>", line 860, in get_code
  File "<frozen importlib._bootstrap_external>", line 791, in source_to_code
  File "<frozen importlib._bootstrap>", line 219, in _call_with_frames_removed
  File "/opt/airflow/dags/process_users_dag.py", line 9
    USERS_JSON_FILENAME =
                         ^
SyntaxError: invalid syntax
[2022-06-03 15:49:12,183] {processor.py:653} WARNING - No viable dags retrieved from /opt/airflow/dags/process_users_dag.py
[2022-06-03 15:49:12,214] {processor.py:161} INFO - Processing /opt/airflow/dags/process_users_dag.py took 0.048 seconds
[2022-06-03 15:49:42,300] {processor.py:153} INFO - Started process (PID=2661) to work on /opt/airflow/dags/process_users_dag.py
[2022-06-03 15:49:42,301] {processor.py:641} INFO - Processing file /opt/airflow/dags/process_users_dag.py for tasks to queue
[2022-06-03 15:49:42,302] {logging_mixin.py:115} INFO - [2022-06-03 15:49:42,302] {dagbag.py:507} INFO - Filling up the DagBag from /opt/airflow/dags/process_users_dag.py
[2022-06-03 15:49:42,306] {logging_mixin.py:115} INFO - [2022-06-03 15:49:42,305] {dagbag.py:320} ERROR - Failed to import: /opt/airflow/dags/process_users_dag.py
Traceback (most recent call last):
  File "/home/airflow/.local/lib/python3.7/site-packages/airflow/models/dagbag.py", line 317, in parse
    loader.exec_module(new_module)
  File "<frozen importlib._bootstrap_external>", line 724, in exec_module
  File "<frozen importlib._bootstrap_external>", line 860, in get_code
  File "<frozen importlib._bootstrap_external>", line 791, in source_to_code
  File "<frozen importlib._bootstrap>", line 219, in _call_with_frames_removed
  File "/opt/airflow/dags/process_users_dag.py", line 9
    USERS_JSON_FILENAME =
                         ^
SyntaxError: invalid syntax
[2022-06-03 15:49:42,306] {processor.py:653} WARNING - No viable dags retrieved from /opt/airflow/dags/process_users_dag.py
[2022-06-03 15:49:42,332] {processor.py:161} INFO - Processing /opt/airflow/dags/process_users_dag.py took 0.041 seconds
[2022-06-03 15:49:55,334] {processor.py:153} INFO - Started process (PID=2671) to work on /opt/airflow/dags/process_users_dag.py
[2022-06-03 15:49:55,341] {processor.py:641} INFO - Processing file /opt/airflow/dags/process_users_dag.py for tasks to queue
[2022-06-03 15:49:55,341] {logging_mixin.py:115} INFO - [2022-06-03 15:49:55,341] {dagbag.py:507} INFO - Filling up the DagBag from /opt/airflow/dags/process_users_dag.py
[2022-06-03 15:49:55,344] {logging_mixin.py:115} INFO - [2022-06-03 15:49:55,343] {dagbag.py:320} ERROR - Failed to import: /opt/airflow/dags/process_users_dag.py
Traceback (most recent call last):
  File "/home/airflow/.local/lib/python3.7/site-packages/airflow/models/dagbag.py", line 317, in parse
    loader.exec_module(new_module)
  File "<frozen importlib._bootstrap_external>", line 724, in exec_module
  File "<frozen importlib._bootstrap_external>", line 860, in get_code
  File "<frozen importlib._bootstrap_external>", line 791, in source_to_code
  File "<frozen importlib._bootstrap>", line 219, in _call_with_frames_removed
  File "/opt/airflow/dags/process_users_dag.py", line 11
    @dag(start_date=datetime(), schedule_interval"@daily", catchup=False)
                                                        ^
SyntaxError: invalid syntax
[2022-06-03 15:49:55,344] {processor.py:653} WARNING - No viable dags retrieved from /opt/airflow/dags/process_users_dag.py
[2022-06-03 15:49:55,376] {processor.py:161} INFO - Processing /opt/airflow/dags/process_users_dag.py took 0.045 seconds
[2022-06-03 15:50:02,420] {processor.py:153} INFO - Started process (PID=2673) to work on /opt/airflow/dags/process_users_dag.py
[2022-06-03 15:50:02,427] {processor.py:641} INFO - Processing file /opt/airflow/dags/process_users_dag.py for tasks to queue
[2022-06-03 15:50:02,427] {logging_mixin.py:115} INFO - [2022-06-03 15:50:02,427] {dagbag.py:507} INFO - Filling up the DagBag from /opt/airflow/dags/process_users_dag.py
[2022-06-03 15:50:02,430] {logging_mixin.py:115} INFO - [2022-06-03 15:50:02,429] {dagbag.py:320} ERROR - Failed to import: /opt/airflow/dags/process_users_dag.py
Traceback (most recent call last):
  File "/home/airflow/.local/lib/python3.7/site-packages/airflow/models/dagbag.py", line 317, in parse
    loader.exec_module(new_module)
  File "<frozen importlib._bootstrap_external>", line 724, in exec_module
  File "<frozen importlib._bootstrap_external>", line 860, in get_code
  File "<frozen importlib._bootstrap_external>", line 791, in source_to_code
  File "<frozen importlib._bootstrap>", line 219, in _call_with_frames_removed
  File "/opt/airflow/dags/process_users_dag.py", line 11
    @dag(start_date=datetime(), schedule_interval"@daily", catchup=False)
                                                        ^
SyntaxError: invalid syntax
[2022-06-03 15:50:02,430] {processor.py:653} WARNING - No viable dags retrieved from /opt/airflow/dags/process_users_dag.py
[2022-06-03 15:50:02,457] {processor.py:161} INFO - Processing /opt/airflow/dags/process_users_dag.py took 0.041 seconds
[2022-06-03 15:50:16,465] {processor.py:153} INFO - Started process (PID=2683) to work on /opt/airflow/dags/process_users_dag.py
[2022-06-03 15:50:16,466] {processor.py:641} INFO - Processing file /opt/airflow/dags/process_users_dag.py for tasks to queue
[2022-06-03 15:50:16,467] {logging_mixin.py:115} INFO - [2022-06-03 15:50:16,467] {dagbag.py:507} INFO - Filling up the DagBag from /opt/airflow/dags/process_users_dag.py
[2022-06-03 15:50:16,469] {logging_mixin.py:115} INFO - [2022-06-03 15:50:16,468] {dagbag.py:320} ERROR - Failed to import: /opt/airflow/dags/process_users_dag.py
Traceback (most recent call last):
  File "/home/airflow/.local/lib/python3.7/site-packages/airflow/models/dagbag.py", line 317, in parse
    loader.exec_module(new_module)
  File "<frozen importlib._bootstrap_external>", line 724, in exec_module
  File "<frozen importlib._bootstrap_external>", line 860, in get_code
  File "<frozen importlib._bootstrap_external>", line 791, in source_to_code
  File "<frozen importlib._bootstrap>", line 219, in _call_with_frames_removed
  File "/opt/airflow/dags/process_users_dag.py", line 21
    df = pd.read_csv(path_to_csv)
                                    ^
IndentationError: unindent does not match any outer indentation level
[2022-06-03 15:50:16,470] {processor.py:653} WARNING - No viable dags retrieved from /opt/airflow/dags/process_users_dag.py
[2022-06-03 15:50:16,499] {processor.py:161} INFO - Processing /opt/airflow/dags/process_users_dag.py took 0.037 seconds
[2022-06-03 15:50:46,577] {processor.py:153} INFO - Started process (PID=2712) to work on /opt/airflow/dags/process_users_dag.py
[2022-06-03 15:50:46,584] {processor.py:641} INFO - Processing file /opt/airflow/dags/process_users_dag.py for tasks to queue
[2022-06-03 15:50:46,585] {logging_mixin.py:115} INFO - [2022-06-03 15:50:46,585] {dagbag.py:507} INFO - Filling up the DagBag from /opt/airflow/dags/process_users_dag.py
[2022-06-03 15:50:46,590] {logging_mixin.py:115} INFO - [2022-06-03 15:50:46,588] {dagbag.py:320} ERROR - Failed to import: /opt/airflow/dags/process_users_dag.py
Traceback (most recent call last):
  File "/home/airflow/.local/lib/python3.7/site-packages/airflow/models/dagbag.py", line 317, in parse
    loader.exec_module(new_module)
  File "<frozen importlib._bootstrap_external>", line 724, in exec_module
  File "<frozen importlib._bootstrap_external>", line 860, in get_code
  File "<frozen importlib._bootstrap_external>", line 791, in source_to_code
  File "<frozen importlib._bootstrap>", line 219, in _call_with_frames_removed
  File "/opt/airflow/dags/process_users_dag.py", line 21
    df = pd.read_csv(path_to_csv)
                                    ^
IndentationError: unindent does not match any outer indentation level
[2022-06-03 15:50:46,591] {processor.py:653} WARNING - No viable dags retrieved from /opt/airflow/dags/process_users_dag.py
[2022-06-03 15:50:46,629] {processor.py:161} INFO - Processing /opt/airflow/dags/process_users_dag.py took 0.056 seconds
[2022-06-03 15:51:09,732] {processor.py:153} INFO - Started process (PID=2722) to work on /opt/airflow/dags/process_users_dag.py
[2022-06-03 15:51:09,740] {processor.py:641} INFO - Processing file /opt/airflow/dags/process_users_dag.py for tasks to queue
[2022-06-03 15:51:09,741] {logging_mixin.py:115} INFO - [2022-06-03 15:51:09,741] {dagbag.py:507} INFO - Filling up the DagBag from /opt/airflow/dags/process_users_dag.py
[2022-06-03 15:51:09,746] {logging_mixin.py:115} INFO - [2022-06-03 15:51:09,745] {dagbag.py:320} ERROR - Failed to import: /opt/airflow/dags/process_users_dag.py
Traceback (most recent call last):
  File "/home/airflow/.local/lib/python3.7/site-packages/airflow/models/dagbag.py", line 317, in parse
    loader.exec_module(new_module)
  File "<frozen importlib._bootstrap_external>", line 724, in exec_module
  File "<frozen importlib._bootstrap_external>", line 860, in get_code
  File "<frozen importlib._bootstrap_external>", line 791, in source_to_code
  File "<frozen importlib._bootstrap>", line 219, in _call_with_frames_removed
  File "/opt/airflow/dags/process_users_dag.py", line 23
    df = pd.read_csv(path_to_csv)
                                    ^
IndentationError: unindent does not match any outer indentation level
[2022-06-03 15:51:09,747] {processor.py:653} WARNING - No viable dags retrieved from /opt/airflow/dags/process_users_dag.py
[2022-06-03 15:51:09,810] {processor.py:161} INFO - Processing /opt/airflow/dags/process_users_dag.py took 0.089 seconds
[2022-06-03 15:51:39,906] {processor.py:153} INFO - Started process (PID=2750) to work on /opt/airflow/dags/process_users_dag.py
[2022-06-03 15:51:39,913] {processor.py:641} INFO - Processing file /opt/airflow/dags/process_users_dag.py for tasks to queue
[2022-06-03 15:51:39,915] {logging_mixin.py:115} INFO - [2022-06-03 15:51:39,915] {dagbag.py:507} INFO - Filling up the DagBag from /opt/airflow/dags/process_users_dag.py
[2022-06-03 15:51:39,919] {logging_mixin.py:115} INFO - [2022-06-03 15:51:39,918] {dagbag.py:320} ERROR - Failed to import: /opt/airflow/dags/process_users_dag.py
Traceback (most recent call last):
  File "/home/airflow/.local/lib/python3.7/site-packages/airflow/models/dagbag.py", line 317, in parse
    loader.exec_module(new_module)
  File "<frozen importlib._bootstrap_external>", line 724, in exec_module
  File "<frozen importlib._bootstrap_external>", line 860, in get_code
  File "<frozen importlib._bootstrap_external>", line 791, in source_to_code
  File "<frozen importlib._bootstrap>", line 219, in _call_with_frames_removed
  File "/opt/airflow/dags/process_users_dag.py", line 23
    df = pd.read_csv(path_to_csv)
                                    ^
IndentationError: unindent does not match any outer indentation level
[2022-06-03 15:51:39,919] {processor.py:653} WARNING - No viable dags retrieved from /opt/airflow/dags/process_users_dag.py
[2022-06-03 15:51:39,947] {processor.py:161} INFO - Processing /opt/airflow/dags/process_users_dag.py took 0.048 seconds
[2022-06-03 15:51:54,940] {processor.py:153} INFO - Started process (PID=2761) to work on /opt/airflow/dags/process_users_dag.py
[2022-06-03 15:51:54,947] {processor.py:641} INFO - Processing file /opt/airflow/dags/process_users_dag.py for tasks to queue
[2022-06-03 15:51:54,948] {logging_mixin.py:115} INFO - [2022-06-03 15:51:54,948] {dagbag.py:507} INFO - Filling up the DagBag from /opt/airflow/dags/process_users_dag.py
[2022-06-03 15:51:56,828] {logging_mixin.py:115} INFO - [2022-06-03 15:51:56,827] {dagbag.py:320} ERROR - Failed to import: /opt/airflow/dags/process_users_dag.py
Traceback (most recent call last):
  File "/home/airflow/.local/lib/python3.7/site-packages/airflow/models/dagbag.py", line 317, in parse
    loader.exec_module(new_module)
  File "<frozen importlib._bootstrap_external>", line 728, in exec_module
  File "<frozen importlib._bootstrap>", line 219, in _call_with_frames_removed
  File "/opt/airflow/dags/process_users_dag.py", line 11, in <module>
    USERS_JSON_FILENAME = Variable.get("users_json_filename")
  File "/home/airflow/.local/lib/python3.7/site-packages/airflow/models/variable.py", line 138, in get
    raise KeyError(f'Variable {key} does not exist')
KeyError: 'Variable users_json_filename does not exist'
[2022-06-03 15:51:56,829] {processor.py:653} WARNING - No viable dags retrieved from /opt/airflow/dags/process_users_dag.py
[2022-06-03 15:51:56,847] {processor.py:161} INFO - Processing /opt/airflow/dags/process_users_dag.py took 1.911 seconds
[2022-06-03 15:52:25,329] {processor.py:153} INFO - Started process (PID=2782) to work on /opt/airflow/dags/process_users_dag.py
[2022-06-03 15:52:25,331] {processor.py:641} INFO - Processing file /opt/airflow/dags/process_users_dag.py for tasks to queue
[2022-06-03 15:52:25,333] {logging_mixin.py:115} INFO - [2022-06-03 15:52:25,333] {dagbag.py:507} INFO - Filling up the DagBag from /opt/airflow/dags/process_users_dag.py
[2022-06-03 15:52:25,994] {logging_mixin.py:115} INFO - [2022-06-03 15:52:25,992] {dagbag.py:320} ERROR - Failed to import: /opt/airflow/dags/process_users_dag.py
Traceback (most recent call last):
  File "/home/airflow/.local/lib/python3.7/site-packages/airflow/models/dagbag.py", line 317, in parse
    loader.exec_module(new_module)
  File "<frozen importlib._bootstrap_external>", line 728, in exec_module
  File "<frozen importlib._bootstrap>", line 219, in _call_with_frames_removed
  File "/opt/airflow/dags/process_users_dag.py", line 11, in <module>
    USERS_JSON_FILENAME = Variable.get("users_json_filename")
  File "/home/airflow/.local/lib/python3.7/site-packages/airflow/models/variable.py", line 138, in get
    raise KeyError(f'Variable {key} does not exist')
KeyError: 'Variable users_json_filename does not exist'
[2022-06-03 15:52:25,995] {processor.py:653} WARNING - No viable dags retrieved from /opt/airflow/dags/process_users_dag.py
[2022-06-03 15:52:26,015] {processor.py:161} INFO - Processing /opt/airflow/dags/process_users_dag.py took 0.701 seconds
[2022-06-03 15:52:35,346] {processor.py:153} INFO - Started process (PID=2794) to work on /opt/airflow/dags/process_users_dag.py
[2022-06-03 15:52:35,346] {processor.py:641} INFO - Processing file /opt/airflow/dags/process_users_dag.py for tasks to queue
[2022-06-03 15:52:35,347] {logging_mixin.py:115} INFO - [2022-06-03 15:52:35,347] {dagbag.py:507} INFO - Filling up the DagBag from /opt/airflow/dags/process_users_dag.py
[2022-06-03 15:52:35,938] {logging_mixin.py:115} INFO - [2022-06-03 15:52:35,937] {dagbag.py:320} ERROR - Failed to import: /opt/airflow/dags/process_users_dag.py
Traceback (most recent call last):
  File "/home/airflow/.local/lib/python3.7/site-packages/airflow/models/dagbag.py", line 317, in parse
    loader.exec_module(new_module)
  File "<frozen importlib._bootstrap_external>", line 728, in exec_module
  File "<frozen importlib._bootstrap>", line 219, in _call_with_frames_removed
  File "/opt/airflow/dags/process_users_dag.py", line 11, in <module>
    USERS_JSON_FILENAME = Variable.get("users_json_filename")
  File "/home/airflow/.local/lib/python3.7/site-packages/airflow/models/variable.py", line 138, in get
    raise KeyError(f'Variable {key} does not exist')
KeyError: 'Variable users_json_filename does not exist'
[2022-06-03 15:52:35,939] {processor.py:653} WARNING - No viable dags retrieved from /opt/airflow/dags/process_users_dag.py
[2022-06-03 15:52:35,957] {processor.py:161} INFO - Processing /opt/airflow/dags/process_users_dag.py took 0.614 seconds
[2022-06-03 15:53:06,036] {processor.py:153} INFO - Started process (PID=2824) to work on /opt/airflow/dags/process_users_dag.py
[2022-06-03 15:53:06,043] {processor.py:641} INFO - Processing file /opt/airflow/dags/process_users_dag.py for tasks to queue
[2022-06-03 15:53:06,044] {logging_mixin.py:115} INFO - [2022-06-03 15:53:06,044] {dagbag.py:507} INFO - Filling up the DagBag from /opt/airflow/dags/process_users_dag.py
[2022-06-03 15:53:06,633] {logging_mixin.py:115} INFO - [2022-06-03 15:53:06,632] {dagbag.py:320} ERROR - Failed to import: /opt/airflow/dags/process_users_dag.py
Traceback (most recent call last):
  File "/home/airflow/.local/lib/python3.7/site-packages/airflow/models/dagbag.py", line 317, in parse
    loader.exec_module(new_module)
  File "<frozen importlib._bootstrap_external>", line 728, in exec_module
  File "<frozen importlib._bootstrap>", line 219, in _call_with_frames_removed
  File "/opt/airflow/dags/process_users_dag.py", line 11, in <module>
    USERS_JSON_FILENAME = Variable.get("users_json_filename")
  File "/home/airflow/.local/lib/python3.7/site-packages/airflow/models/variable.py", line 138, in get
    raise KeyError(f'Variable {key} does not exist')
KeyError: 'Variable users_json_filename does not exist'
[2022-06-03 15:53:06,634] {processor.py:653} WARNING - No viable dags retrieved from /opt/airflow/dags/process_users_dag.py
[2022-06-03 15:53:06,653] {processor.py:161} INFO - Processing /opt/airflow/dags/process_users_dag.py took 0.625 seconds
[2022-06-03 15:53:37,142] {processor.py:153} INFO - Started process (PID=2845) to work on /opt/airflow/dags/process_users_dag.py
[2022-06-03 15:53:37,144] {processor.py:641} INFO - Processing file /opt/airflow/dags/process_users_dag.py for tasks to queue
[2022-06-03 15:53:37,146] {logging_mixin.py:115} INFO - [2022-06-03 15:53:37,146] {dagbag.py:507} INFO - Filling up the DagBag from /opt/airflow/dags/process_users_dag.py
[2022-06-03 15:53:37,759] {logging_mixin.py:115} INFO - [2022-06-03 15:53:37,758] {dagbag.py:320} ERROR - Failed to import: /opt/airflow/dags/process_users_dag.py
Traceback (most recent call last):
  File "/home/airflow/.local/lib/python3.7/site-packages/airflow/models/dagbag.py", line 317, in parse
    loader.exec_module(new_module)
  File "<frozen importlib._bootstrap_external>", line 728, in exec_module
  File "<frozen importlib._bootstrap>", line 219, in _call_with_frames_removed
  File "/opt/airflow/dags/process_users_dag.py", line 11, in <module>
    USERS_JSON_FILENAME = Variable.get("users_json_filename")
  File "/home/airflow/.local/lib/python3.7/site-packages/airflow/models/variable.py", line 138, in get
    raise KeyError(f'Variable {key} does not exist')
KeyError: 'Variable users_json_filename does not exist'
[2022-06-03 15:53:37,760] {processor.py:653} WARNING - No viable dags retrieved from /opt/airflow/dags/process_users_dag.py
[2022-06-03 15:53:37,777] {processor.py:161} INFO - Processing /opt/airflow/dags/process_users_dag.py took 0.646 seconds
[2022-06-03 15:54:07,872] {processor.py:153} INFO - Started process (PID=2874) to work on /opt/airflow/dags/process_users_dag.py
[2022-06-03 15:54:07,873] {processor.py:641} INFO - Processing file /opt/airflow/dags/process_users_dag.py for tasks to queue
[2022-06-03 15:54:07,874] {logging_mixin.py:115} INFO - [2022-06-03 15:54:07,874] {dagbag.py:507} INFO - Filling up the DagBag from /opt/airflow/dags/process_users_dag.py
[2022-06-03 15:54:08,859] {logging_mixin.py:115} INFO - [2022-06-03 15:54:08,857] {dagbag.py:320} ERROR - Failed to import: /opt/airflow/dags/process_users_dag.py
Traceback (most recent call last):
  File "/home/airflow/.local/lib/python3.7/site-packages/airflow/models/dagbag.py", line 317, in parse
    loader.exec_module(new_module)
  File "<frozen importlib._bootstrap_external>", line 728, in exec_module
  File "<frozen importlib._bootstrap>", line 219, in _call_with_frames_removed
  File "/opt/airflow/dags/process_users_dag.py", line 11, in <module>
    USERS_JSON_FILENAME = Variable.get("users_json_filename")
  File "/home/airflow/.local/lib/python3.7/site-packages/airflow/models/variable.py", line 138, in get
    raise KeyError(f'Variable {key} does not exist')
KeyError: 'Variable users_json_filename does not exist'
[2022-06-03 15:54:08,860] {processor.py:653} WARNING - No viable dags retrieved from /opt/airflow/dags/process_users_dag.py
[2022-06-03 15:54:08,877] {processor.py:161} INFO - Processing /opt/airflow/dags/process_users_dag.py took 1.011 seconds
[2022-06-03 15:54:38,992] {processor.py:153} INFO - Started process (PID=2895) to work on /opt/airflow/dags/process_users_dag.py
[2022-06-03 15:54:38,993] {processor.py:641} INFO - Processing file /opt/airflow/dags/process_users_dag.py for tasks to queue
[2022-06-03 15:54:38,995] {logging_mixin.py:115} INFO - [2022-06-03 15:54:38,995] {dagbag.py:507} INFO - Filling up the DagBag from /opt/airflow/dags/process_users_dag.py
[2022-06-03 15:54:39,626] {logging_mixin.py:115} INFO - [2022-06-03 15:54:39,625] {dagbag.py:320} ERROR - Failed to import: /opt/airflow/dags/process_users_dag.py
Traceback (most recent call last):
  File "/home/airflow/.local/lib/python3.7/site-packages/airflow/models/dagbag.py", line 317, in parse
    loader.exec_module(new_module)
  File "<frozen importlib._bootstrap_external>", line 728, in exec_module
  File "<frozen importlib._bootstrap>", line 219, in _call_with_frames_removed
  File "/opt/airflow/dags/process_users_dag.py", line 11, in <module>
    USERS_JSON_FILENAME = Variable.get("users_json_filename")
  File "/home/airflow/.local/lib/python3.7/site-packages/airflow/models/variable.py", line 138, in get
    raise KeyError(f'Variable {key} does not exist')
KeyError: 'Variable users_json_filename does not exist'
[2022-06-03 15:54:39,627] {processor.py:653} WARNING - No viable dags retrieved from /opt/airflow/dags/process_users_dag.py
[2022-06-03 15:54:39,645] {processor.py:161} INFO - Processing /opt/airflow/dags/process_users_dag.py took 0.664 seconds
[2022-06-03 15:55:09,746] {processor.py:153} INFO - Started process (PID=2923) to work on /opt/airflow/dags/process_users_dag.py
[2022-06-03 15:55:09,753] {processor.py:641} INFO - Processing file /opt/airflow/dags/process_users_dag.py for tasks to queue
[2022-06-03 15:55:09,754] {logging_mixin.py:115} INFO - [2022-06-03 15:55:09,754] {dagbag.py:507} INFO - Filling up the DagBag from /opt/airflow/dags/process_users_dag.py
[2022-06-03 15:55:10,472] {logging_mixin.py:115} INFO - [2022-06-03 15:55:10,470] {dagbag.py:320} ERROR - Failed to import: /opt/airflow/dags/process_users_dag.py
Traceback (most recent call last):
  File "/home/airflow/.local/lib/python3.7/site-packages/airflow/models/dagbag.py", line 317, in parse
    loader.exec_module(new_module)
  File "<frozen importlib._bootstrap_external>", line 728, in exec_module
  File "<frozen importlib._bootstrap>", line 219, in _call_with_frames_removed
  File "/opt/airflow/dags/process_users_dag.py", line 11, in <module>
    USERS_JSON_FILENAME = Variable.get("users_json_filename")
  File "/home/airflow/.local/lib/python3.7/site-packages/airflow/models/variable.py", line 138, in get
    raise KeyError(f'Variable {key} does not exist')
KeyError: 'Variable users_json_filename does not exist'
[2022-06-03 15:55:10,472] {processor.py:653} WARNING - No viable dags retrieved from /opt/airflow/dags/process_users_dag.py
[2022-06-03 15:55:10,487] {processor.py:161} INFO - Processing /opt/airflow/dags/process_users_dag.py took 0.746 seconds
[2022-06-03 15:55:40,851] {processor.py:153} INFO - Started process (PID=2947) to work on /opt/airflow/dags/process_users_dag.py
[2022-06-03 15:55:40,853] {processor.py:641} INFO - Processing file /opt/airflow/dags/process_users_dag.py for tasks to queue
[2022-06-03 15:55:40,855] {logging_mixin.py:115} INFO - [2022-06-03 15:55:40,855] {dagbag.py:507} INFO - Filling up the DagBag from /opt/airflow/dags/process_users_dag.py
[2022-06-03 15:55:41,538] {logging_mixin.py:115} INFO - [2022-06-03 15:55:41,537] {dagbag.py:320} ERROR - Failed to import: /opt/airflow/dags/process_users_dag.py
Traceback (most recent call last):
  File "/home/airflow/.local/lib/python3.7/site-packages/airflow/models/dagbag.py", line 317, in parse
    loader.exec_module(new_module)
  File "<frozen importlib._bootstrap_external>", line 728, in exec_module
  File "<frozen importlib._bootstrap>", line 219, in _call_with_frames_removed
  File "/opt/airflow/dags/process_users_dag.py", line 11, in <module>
    USERS_JSON_FILENAME = Variable.get("users_json_filename")
  File "/home/airflow/.local/lib/python3.7/site-packages/airflow/models/variable.py", line 138, in get
    raise KeyError(f'Variable {key} does not exist')
KeyError: 'Variable users_json_filename does not exist'
[2022-06-03 15:55:41,538] {processor.py:653} WARNING - No viable dags retrieved from /opt/airflow/dags/process_users_dag.py
[2022-06-03 15:55:41,558] {processor.py:161} INFO - Processing /opt/airflow/dags/process_users_dag.py took 0.720 seconds
[2022-06-03 15:56:11,631] {processor.py:153} INFO - Started process (PID=2968) to work on /opt/airflow/dags/process_users_dag.py
[2022-06-03 15:56:11,632] {processor.py:641} INFO - Processing file /opt/airflow/dags/process_users_dag.py for tasks to queue
[2022-06-03 15:56:11,633] {logging_mixin.py:115} INFO - [2022-06-03 15:56:11,632] {dagbag.py:507} INFO - Filling up the DagBag from /opt/airflow/dags/process_users_dag.py
[2022-06-03 15:56:12,227] {logging_mixin.py:115} INFO - [2022-06-03 15:56:12,226] {dagbag.py:320} ERROR - Failed to import: /opt/airflow/dags/process_users_dag.py
Traceback (most recent call last):
  File "/home/airflow/.local/lib/python3.7/site-packages/airflow/models/dagbag.py", line 317, in parse
    loader.exec_module(new_module)
  File "<frozen importlib._bootstrap_external>", line 728, in exec_module
  File "<frozen importlib._bootstrap>", line 219, in _call_with_frames_removed
  File "/opt/airflow/dags/process_users_dag.py", line 11, in <module>
    USERS_JSON_FILENAME = Variable.get("users_json_filename")
  File "/home/airflow/.local/lib/python3.7/site-packages/airflow/models/variable.py", line 138, in get
    raise KeyError(f'Variable {key} does not exist')
KeyError: 'Variable users_json_filename does not exist'
[2022-06-03 15:56:12,228] {processor.py:653} WARNING - No viable dags retrieved from /opt/airflow/dags/process_users_dag.py
[2022-06-03 15:56:12,247] {processor.py:161} INFO - Processing /opt/airflow/dags/process_users_dag.py took 0.622 seconds
[2022-06-03 15:56:42,707] {processor.py:153} INFO - Started process (PID=2995) to work on /opt/airflow/dags/process_users_dag.py
[2022-06-03 15:56:42,708] {processor.py:641} INFO - Processing file /opt/airflow/dags/process_users_dag.py for tasks to queue
[2022-06-03 15:56:42,709] {logging_mixin.py:115} INFO - [2022-06-03 15:56:42,709] {dagbag.py:507} INFO - Filling up the DagBag from /opt/airflow/dags/process_users_dag.py
[2022-06-03 15:56:43,404] {logging_mixin.py:115} INFO - [2022-06-03 15:56:43,403] {dagbag.py:320} ERROR - Failed to import: /opt/airflow/dags/process_users_dag.py
Traceback (most recent call last):
  File "/home/airflow/.local/lib/python3.7/site-packages/airflow/models/dagbag.py", line 317, in parse
    loader.exec_module(new_module)
  File "<frozen importlib._bootstrap_external>", line 728, in exec_module
  File "<frozen importlib._bootstrap>", line 219, in _call_with_frames_removed
  File "/opt/airflow/dags/process_users_dag.py", line 11, in <module>
    USERS_JSON_FILENAME = Variable.get("users_json_filename")
  File "/home/airflow/.local/lib/python3.7/site-packages/airflow/models/variable.py", line 138, in get
    raise KeyError(f'Variable {key} does not exist')
KeyError: 'Variable users_json_filename does not exist'
[2022-06-03 15:56:43,405] {processor.py:653} WARNING - No viable dags retrieved from /opt/airflow/dags/process_users_dag.py
[2022-06-03 15:56:43,423] {processor.py:161} INFO - Processing /opt/airflow/dags/process_users_dag.py took 0.722 seconds
[2022-06-03 15:57:06,050] {processor.py:153} INFO - Started process (PID=3015) to work on /opt/airflow/dags/process_users_dag.py
[2022-06-03 15:57:06,051] {processor.py:641} INFO - Processing file /opt/airflow/dags/process_users_dag.py for tasks to queue
[2022-06-03 15:57:06,052] {logging_mixin.py:115} INFO - [2022-06-03 15:57:06,052] {dagbag.py:507} INFO - Filling up the DagBag from /opt/airflow/dags/process_users_dag.py
[2022-06-03 15:57:06,652] {logging_mixin.py:115} INFO - [2022-06-03 15:57:06,651] {dagbag.py:320} ERROR - Failed to import: /opt/airflow/dags/process_users_dag.py
Traceback (most recent call last):
  File "/home/airflow/.local/lib/python3.7/site-packages/airflow/models/dagbag.py", line 317, in parse
    loader.exec_module(new_module)
  File "<frozen importlib._bootstrap_external>", line 728, in exec_module
  File "<frozen importlib._bootstrap>", line 219, in _call_with_frames_removed
  File "/opt/airflow/dags/process_users_dag.py", line 11, in <module>
    USERS_JSON_FILENAME = Variable.get("users_json_filename")
  File "/home/airflow/.local/lib/python3.7/site-packages/airflow/models/variable.py", line 138, in get
    raise KeyError(f'Variable {key} does not exist')
KeyError: 'Variable users_json_filename does not exist'
[2022-06-03 15:57:06,653] {processor.py:653} WARNING - No viable dags retrieved from /opt/airflow/dags/process_users_dag.py
[2022-06-03 15:57:06,671] {processor.py:161} INFO - Processing /opt/airflow/dags/process_users_dag.py took 0.625 seconds
[2022-06-03 15:57:24,459] {processor.py:153} INFO - Started process (PID=3025) to work on /opt/airflow/dags/process_users_dag.py
[2022-06-03 15:57:24,460] {processor.py:641} INFO - Processing file /opt/airflow/dags/process_users_dag.py for tasks to queue
[2022-06-03 15:57:24,461] {logging_mixin.py:115} INFO - [2022-06-03 15:57:24,460] {dagbag.py:507} INFO - Filling up the DagBag from /opt/airflow/dags/process_users_dag.py
[2022-06-03 15:57:25,434] {logging_mixin.py:115} INFO - [2022-06-03 15:57:25,433] {dagbag.py:320} ERROR - Failed to import: /opt/airflow/dags/process_users_dag.py
Traceback (most recent call last):
  File "/home/airflow/.local/lib/python3.7/site-packages/airflow/models/dagbag.py", line 317, in parse
    loader.exec_module(new_module)
  File "<frozen importlib._bootstrap_external>", line 728, in exec_module
  File "<frozen importlib._bootstrap>", line 219, in _call_with_frames_removed
  File "/opt/airflow/dags/process_users_dag.py", line 11, in <module>
    USERS_JSON_FILENAME = Variable.get("users_json_filename")
  File "/home/airflow/.local/lib/python3.7/site-packages/airflow/models/variable.py", line 138, in get
    raise KeyError(f'Variable {key} does not exist')
KeyError: 'Variable users_json_filename does not exist'
[2022-06-03 15:57:25,434] {processor.py:653} WARNING - No viable dags retrieved from /opt/airflow/dags/process_users_dag.py
[2022-06-03 15:57:25,454] {processor.py:161} INFO - Processing /opt/airflow/dags/process_users_dag.py took 1.001 seconds
[2022-06-03 15:57:55,559] {processor.py:153} INFO - Started process (PID=3055) to work on /opt/airflow/dags/process_users_dag.py
[2022-06-03 15:57:55,560] {processor.py:641} INFO - Processing file /opt/airflow/dags/process_users_dag.py for tasks to queue
[2022-06-03 15:57:55,560] {logging_mixin.py:115} INFO - [2022-06-03 15:57:55,560] {dagbag.py:507} INFO - Filling up the DagBag from /opt/airflow/dags/process_users_dag.py
[2022-06-03 15:57:56,244] {logging_mixin.py:115} INFO - [2022-06-03 15:57:56,243] {dagbag.py:320} ERROR - Failed to import: /opt/airflow/dags/process_users_dag.py
Traceback (most recent call last):
  File "/home/airflow/.local/lib/python3.7/site-packages/airflow/models/dagbag.py", line 317, in parse
    loader.exec_module(new_module)
  File "<frozen importlib._bootstrap_external>", line 728, in exec_module
  File "<frozen importlib._bootstrap>", line 219, in _call_with_frames_removed
  File "/opt/airflow/dags/process_users_dag.py", line 11, in <module>
    USERS_JSON_FILENAME = Variable.get("users_json_filename")
  File "/home/airflow/.local/lib/python3.7/site-packages/airflow/models/variable.py", line 138, in get
    raise KeyError(f'Variable {key} does not exist')
KeyError: 'Variable users_json_filename does not exist'
[2022-06-03 15:57:56,245] {processor.py:653} WARNING - No viable dags retrieved from /opt/airflow/dags/process_users_dag.py
[2022-06-03 15:57:56,259] {processor.py:161} INFO - Processing /opt/airflow/dags/process_users_dag.py took 0.704 seconds
[2022-06-03 15:57:59,300] {processor.py:153} INFO - Started process (PID=3057) to work on /opt/airflow/dags/process_users_dag.py
[2022-06-03 15:57:59,302] {processor.py:641} INFO - Processing file /opt/airflow/dags/process_users_dag.py for tasks to queue
[2022-06-03 15:57:59,304] {logging_mixin.py:115} INFO - [2022-06-03 15:57:59,303] {dagbag.py:507} INFO - Filling up the DagBag from /opt/airflow/dags/process_users_dag.py
[2022-06-03 15:58:00,331] {logging_mixin.py:115} INFO - [2022-06-03 15:58:00,330] {dagbag.py:320} ERROR - Failed to import: /opt/airflow/dags/process_users_dag.py
Traceback (most recent call last):
  File "/home/airflow/.local/lib/python3.7/site-packages/airflow/models/dagbag.py", line 317, in parse
    loader.exec_module(new_module)
  File "<frozen importlib._bootstrap_external>", line 728, in exec_module
  File "<frozen importlib._bootstrap>", line 219, in _call_with_frames_removed
  File "/opt/airflow/dags/process_users_dag.py", line 11, in <module>
    USERS_JSON_FILENAME = Variable.get("users_json_filename")
  File "/home/airflow/.local/lib/python3.7/site-packages/airflow/models/variable.py", line 138, in get
    raise KeyError(f'Variable {key} does not exist')
KeyError: 'Variable users_json_filename does not exist'
[2022-06-03 15:58:00,331] {processor.py:653} WARNING - No viable dags retrieved from /opt/airflow/dags/process_users_dag.py
[2022-06-03 15:58:00,346] {processor.py:161} INFO - Processing /opt/airflow/dags/process_users_dag.py took 1.054 seconds
[2022-06-03 15:58:30,459] {processor.py:153} INFO - Started process (PID=3078) to work on /opt/airflow/dags/process_users_dag.py
[2022-06-03 15:58:30,466] {processor.py:641} INFO - Processing file /opt/airflow/dags/process_users_dag.py for tasks to queue
[2022-06-03 15:58:30,467] {logging_mixin.py:115} INFO - [2022-06-03 15:58:30,467] {dagbag.py:507} INFO - Filling up the DagBag from /opt/airflow/dags/process_users_dag.py
[2022-06-03 15:58:31,098] {logging_mixin.py:115} INFO - [2022-06-03 15:58:31,096] {dagbag.py:320} ERROR - Failed to import: /opt/airflow/dags/process_users_dag.py
Traceback (most recent call last):
  File "/home/airflow/.local/lib/python3.7/site-packages/airflow/models/dagbag.py", line 317, in parse
    loader.exec_module(new_module)
  File "<frozen importlib._bootstrap_external>", line 728, in exec_module
  File "<frozen importlib._bootstrap>", line 219, in _call_with_frames_removed
  File "/opt/airflow/dags/process_users_dag.py", line 11, in <module>
    USERS_JSON_FILENAME = Variable.get("users_json_filename")
  File "/home/airflow/.local/lib/python3.7/site-packages/airflow/models/variable.py", line 138, in get
    raise KeyError(f'Variable {key} does not exist')
KeyError: 'Variable users_json_filename does not exist'
[2022-06-03 15:58:31,098] {processor.py:653} WARNING - No viable dags retrieved from /opt/airflow/dags/process_users_dag.py
[2022-06-03 15:58:31,119] {processor.py:161} INFO - Processing /opt/airflow/dags/process_users_dag.py took 0.667 seconds
[2022-06-03 15:59:01,782] {processor.py:153} INFO - Started process (PID=3108) to work on /opt/airflow/dags/process_users_dag.py
[2022-06-03 15:59:01,782] {processor.py:641} INFO - Processing file /opt/airflow/dags/process_users_dag.py for tasks to queue
[2022-06-03 15:59:01,783] {logging_mixin.py:115} INFO - [2022-06-03 15:59:01,783] {dagbag.py:507} INFO - Filling up the DagBag from /opt/airflow/dags/process_users_dag.py
[2022-06-03 15:59:02,415] {logging_mixin.py:115} INFO - [2022-06-03 15:59:02,414] {dagbag.py:320} ERROR - Failed to import: /opt/airflow/dags/process_users_dag.py
Traceback (most recent call last):
  File "/home/airflow/.local/lib/python3.7/site-packages/airflow/models/dagbag.py", line 317, in parse
    loader.exec_module(new_module)
  File "<frozen importlib._bootstrap_external>", line 728, in exec_module
  File "<frozen importlib._bootstrap>", line 219, in _call_with_frames_removed
  File "/opt/airflow/dags/process_users_dag.py", line 11, in <module>
    USERS_JSON_FILENAME = Variable.get("users_json_filename")
  File "/home/airflow/.local/lib/python3.7/site-packages/airflow/models/variable.py", line 138, in get
    raise KeyError(f'Variable {key} does not exist')
KeyError: 'Variable users_json_filename does not exist'
[2022-06-03 15:59:02,415] {processor.py:653} WARNING - No viable dags retrieved from /opt/airflow/dags/process_users_dag.py
[2022-06-03 15:59:02,427] {processor.py:161} INFO - Processing /opt/airflow/dags/process_users_dag.py took 0.649 seconds
[2022-06-03 15:59:32,542] {processor.py:153} INFO - Started process (PID=3128) to work on /opt/airflow/dags/process_users_dag.py
[2022-06-03 15:59:32,543] {processor.py:641} INFO - Processing file /opt/airflow/dags/process_users_dag.py for tasks to queue
[2022-06-03 15:59:32,544] {logging_mixin.py:115} INFO - [2022-06-03 15:59:32,544] {dagbag.py:507} INFO - Filling up the DagBag from /opt/airflow/dags/process_users_dag.py
[2022-06-03 15:59:33,134] {logging_mixin.py:115} INFO - [2022-06-03 15:59:33,133] {dagbag.py:320} ERROR - Failed to import: /opt/airflow/dags/process_users_dag.py
Traceback (most recent call last):
  File "/home/airflow/.local/lib/python3.7/site-packages/airflow/models/dagbag.py", line 317, in parse
    loader.exec_module(new_module)
  File "<frozen importlib._bootstrap_external>", line 728, in exec_module
  File "<frozen importlib._bootstrap>", line 219, in _call_with_frames_removed
  File "/opt/airflow/dags/process_users_dag.py", line 11, in <module>
    USERS_JSON_FILENAME = Variable.get("users_json_filename")
  File "/home/airflow/.local/lib/python3.7/site-packages/airflow/models/variable.py", line 138, in get
    raise KeyError(f'Variable {key} does not exist')
KeyError: 'Variable users_json_filename does not exist'
[2022-06-03 15:59:33,134] {processor.py:653} WARNING - No viable dags retrieved from /opt/airflow/dags/process_users_dag.py
[2022-06-03 15:59:33,148] {processor.py:161} INFO - Processing /opt/airflow/dags/process_users_dag.py took 0.611 seconds
[2022-06-03 15:59:58,684] {processor.py:153} INFO - Started process (PID=3155) to work on /opt/airflow/dags/process_users_dag.py
[2022-06-03 15:59:58,684] {processor.py:641} INFO - Processing file /opt/airflow/dags/process_users_dag.py for tasks to queue
[2022-06-03 15:59:58,685] {logging_mixin.py:115} INFO - [2022-06-03 15:59:58,685] {dagbag.py:507} INFO - Filling up the DagBag from /opt/airflow/dags/process_users_dag.py
[2022-06-03 15:59:59,606] {logging_mixin.py:115} INFO - [2022-06-03 15:59:59,602] {dagbag.py:320} ERROR - Failed to import: /opt/airflow/dags/process_users_dag.py
Traceback (most recent call last):
  File "/home/airflow/.local/lib/python3.7/site-packages/airflow/models/dagbag.py", line 317, in parse
    loader.exec_module(new_module)
  File "<frozen importlib._bootstrap_external>", line 728, in exec_module
  File "<frozen importlib._bootstrap>", line 219, in _call_with_frames_removed
  File "/opt/airflow/dags/process_users_dag.py", line 11, in <module>
    USERS_JSON_FILENAME = Variable.get("users_json_filename")
  File "/home/airflow/.local/lib/python3.7/site-packages/airflow/models/variable.py", line 138, in get
    raise KeyError(f'Variable {key} does not exist')
KeyError: 'Variable users_json_filename does not exist'
[2022-06-03 15:59:59,607] {processor.py:653} WARNING - No viable dags retrieved from /opt/airflow/dags/process_users_dag.py
[2022-06-03 15:59:59,656] {processor.py:161} INFO - Processing /opt/airflow/dags/process_users_dag.py took 0.980 seconds
[2022-06-03 16:00:29,773] {processor.py:153} INFO - Started process (PID=3179) to work on /opt/airflow/dags/process_users_dag.py
[2022-06-03 16:00:29,774] {processor.py:641} INFO - Processing file /opt/airflow/dags/process_users_dag.py for tasks to queue
[2022-06-03 16:00:29,774] {logging_mixin.py:115} INFO - [2022-06-03 16:00:29,774] {dagbag.py:507} INFO - Filling up the DagBag from /opt/airflow/dags/process_users_dag.py
[2022-06-03 16:00:30,485] {logging_mixin.py:115} INFO - [2022-06-03 16:00:30,483] {dagbag.py:320} ERROR - Failed to import: /opt/airflow/dags/process_users_dag.py
Traceback (most recent call last):
  File "/home/airflow/.local/lib/python3.7/site-packages/airflow/models/dagbag.py", line 317, in parse
    loader.exec_module(new_module)
  File "<frozen importlib._bootstrap_external>", line 728, in exec_module
  File "<frozen importlib._bootstrap>", line 219, in _call_with_frames_removed
  File "/opt/airflow/dags/process_users_dag.py", line 11, in <module>
    USERS_JSON_FILENAME = Variable.get("users_json_filename")
  File "/home/airflow/.local/lib/python3.7/site-packages/airflow/models/variable.py", line 138, in get
    raise KeyError(f'Variable {key} does not exist')
KeyError: 'Variable users_json_filename does not exist'
[2022-06-03 16:00:30,485] {processor.py:653} WARNING - No viable dags retrieved from /opt/airflow/dags/process_users_dag.py
[2022-06-03 16:00:30,500] {processor.py:161} INFO - Processing /opt/airflow/dags/process_users_dag.py took 0.732 seconds
[2022-06-03 16:01:01,176] {processor.py:153} INFO - Started process (PID=3200) to work on /opt/airflow/dags/process_users_dag.py
[2022-06-03 16:01:01,183] {processor.py:641} INFO - Processing file /opt/airflow/dags/process_users_dag.py for tasks to queue
[2022-06-03 16:01:01,184] {logging_mixin.py:115} INFO - [2022-06-03 16:01:01,183] {dagbag.py:507} INFO - Filling up the DagBag from /opt/airflow/dags/process_users_dag.py
[2022-06-03 16:01:01,744] {logging_mixin.py:115} INFO - [2022-06-03 16:01:01,743] {dagbag.py:320} ERROR - Failed to import: /opt/airflow/dags/process_users_dag.py
Traceback (most recent call last):
  File "/home/airflow/.local/lib/python3.7/site-packages/airflow/models/dagbag.py", line 317, in parse
    loader.exec_module(new_module)
  File "<frozen importlib._bootstrap_external>", line 728, in exec_module
  File "<frozen importlib._bootstrap>", line 219, in _call_with_frames_removed
  File "/opt/airflow/dags/process_users_dag.py", line 11, in <module>
    USERS_JSON_FILENAME = Variable.get("users_json_filename")
  File "/home/airflow/.local/lib/python3.7/site-packages/airflow/models/variable.py", line 138, in get
    raise KeyError(f'Variable {key} does not exist')
KeyError: 'Variable users_json_filename does not exist'
[2022-06-03 16:01:01,744] {processor.py:653} WARNING - No viable dags retrieved from /opt/airflow/dags/process_users_dag.py
[2022-06-03 16:01:01,779] {processor.py:161} INFO - Processing /opt/airflow/dags/process_users_dag.py took 0.611 seconds
[2022-06-03 16:01:31,894] {processor.py:153} INFO - Started process (PID=3229) to work on /opt/airflow/dags/process_users_dag.py
[2022-06-03 16:01:31,895] {processor.py:641} INFO - Processing file /opt/airflow/dags/process_users_dag.py for tasks to queue
[2022-06-03 16:01:31,896] {logging_mixin.py:115} INFO - [2022-06-03 16:01:31,896] {dagbag.py:507} INFO - Filling up the DagBag from /opt/airflow/dags/process_users_dag.py
[2022-06-03 16:01:32,529] {logging_mixin.py:115} INFO - [2022-06-03 16:01:32,528] {dagbag.py:320} ERROR - Failed to import: /opt/airflow/dags/process_users_dag.py
Traceback (most recent call last):
  File "/home/airflow/.local/lib/python3.7/site-packages/airflow/models/dagbag.py", line 317, in parse
    loader.exec_module(new_module)
  File "<frozen importlib._bootstrap_external>", line 728, in exec_module
  File "<frozen importlib._bootstrap>", line 219, in _call_with_frames_removed
  File "/opt/airflow/dags/process_users_dag.py", line 11, in <module>
    USERS_JSON_FILENAME = Variable.get("users_json_filename")
  File "/home/airflow/.local/lib/python3.7/site-packages/airflow/models/variable.py", line 138, in get
    raise KeyError(f'Variable {key} does not exist')
KeyError: 'Variable users_json_filename does not exist'
[2022-06-03 16:01:32,529] {processor.py:653} WARNING - No viable dags retrieved from /opt/airflow/dags/process_users_dag.py
[2022-06-03 16:01:32,542] {processor.py:161} INFO - Processing /opt/airflow/dags/process_users_dag.py took 0.656 seconds
[2022-06-03 16:02:02,956] {processor.py:153} INFO - Started process (PID=3250) to work on /opt/airflow/dags/process_users_dag.py
[2022-06-03 16:02:02,962] {processor.py:641} INFO - Processing file /opt/airflow/dags/process_users_dag.py for tasks to queue
[2022-06-03 16:02:02,963] {logging_mixin.py:115} INFO - [2022-06-03 16:02:02,963] {dagbag.py:507} INFO - Filling up the DagBag from /opt/airflow/dags/process_users_dag.py
[2022-06-03 16:02:03,550] {logging_mixin.py:115} INFO - [2022-06-03 16:02:03,548] {dagbag.py:320} ERROR - Failed to import: /opt/airflow/dags/process_users_dag.py
Traceback (most recent call last):
  File "/home/airflow/.local/lib/python3.7/site-packages/airflow/models/dagbag.py", line 317, in parse
    loader.exec_module(new_module)
  File "<frozen importlib._bootstrap_external>", line 728, in exec_module
  File "<frozen importlib._bootstrap>", line 219, in _call_with_frames_removed
  File "/opt/airflow/dags/process_users_dag.py", line 11, in <module>
    USERS_JSON_FILENAME = Variable.get("users_json_filename")
  File "/home/airflow/.local/lib/python3.7/site-packages/airflow/models/variable.py", line 138, in get
    raise KeyError(f'Variable {key} does not exist')
KeyError: 'Variable users_json_filename does not exist'
[2022-06-03 16:02:03,550] {processor.py:653} WARNING - No viable dags retrieved from /opt/airflow/dags/process_users_dag.py
[2022-06-03 16:02:03,570] {processor.py:161} INFO - Processing /opt/airflow/dags/process_users_dag.py took 0.618 seconds
[2022-06-03 16:02:33,696] {processor.py:153} INFO - Started process (PID=3280) to work on /opt/airflow/dags/process_users_dag.py
[2022-06-03 16:02:33,697] {processor.py:641} INFO - Processing file /opt/airflow/dags/process_users_dag.py for tasks to queue
[2022-06-03 16:02:33,699] {logging_mixin.py:115} INFO - [2022-06-03 16:02:33,699] {dagbag.py:507} INFO - Filling up the DagBag from /opt/airflow/dags/process_users_dag.py
[2022-06-03 16:02:34,442] {logging_mixin.py:115} INFO - [2022-06-03 16:02:34,441] {dagbag.py:320} ERROR - Failed to import: /opt/airflow/dags/process_users_dag.py
Traceback (most recent call last):
  File "/home/airflow/.local/lib/python3.7/site-packages/airflow/models/dagbag.py", line 317, in parse
    loader.exec_module(new_module)
  File "<frozen importlib._bootstrap_external>", line 728, in exec_module
  File "<frozen importlib._bootstrap>", line 219, in _call_with_frames_removed
  File "/opt/airflow/dags/process_users_dag.py", line 11, in <module>
    USERS_JSON_FILENAME = Variable.get("users_json_filename")
  File "/home/airflow/.local/lib/python3.7/site-packages/airflow/models/variable.py", line 138, in get
    raise KeyError(f'Variable {key} does not exist')
KeyError: 'Variable users_json_filename does not exist'
[2022-06-03 16:02:34,442] {processor.py:653} WARNING - No viable dags retrieved from /opt/airflow/dags/process_users_dag.py
[2022-06-03 16:02:34,460] {processor.py:161} INFO - Processing /opt/airflow/dags/process_users_dag.py took 0.773 seconds
[2022-06-03 16:02:35,492] {processor.py:153} INFO - Started process (PID=3282) to work on /opt/airflow/dags/process_users_dag.py
[2022-06-03 16:02:35,493] {processor.py:641} INFO - Processing file /opt/airflow/dags/process_users_dag.py for tasks to queue
[2022-06-03 16:02:35,495] {logging_mixin.py:115} INFO - [2022-06-03 16:02:35,494] {dagbag.py:507} INFO - Filling up the DagBag from /opt/airflow/dags/process_users_dag.py
[2022-06-03 16:02:36,102] {logging_mixin.py:115} INFO - [2022-06-03 16:02:36,100] {dagbag.py:320} ERROR - Failed to import: /opt/airflow/dags/process_users_dag.py
Traceback (most recent call last):
  File "/home/airflow/.local/lib/python3.7/site-packages/airflow/models/dagbag.py", line 317, in parse
    loader.exec_module(new_module)
  File "<frozen importlib._bootstrap_external>", line 728, in exec_module
  File "<frozen importlib._bootstrap>", line 219, in _call_with_frames_removed
  File "/opt/airflow/dags/process_users_dag.py", line 12, in <module>
    USERS_JSON_FILENAME = Variable.get("users_json_filename")
  File "/home/airflow/.local/lib/python3.7/site-packages/airflow/models/variable.py", line 138, in get
    raise KeyError(f'Variable {key} does not exist')
KeyError: 'Variable users_json_filename does not exist'
[2022-06-03 16:02:36,102] {processor.py:653} WARNING - No viable dags retrieved from /opt/airflow/dags/process_users_dag.py
[2022-06-03 16:02:36,125] {processor.py:161} INFO - Processing /opt/airflow/dags/process_users_dag.py took 0.637 seconds
[2022-06-03 16:03:06,244] {processor.py:153} INFO - Started process (PID=3303) to work on /opt/airflow/dags/process_users_dag.py
[2022-06-03 16:03:06,244] {processor.py:641} INFO - Processing file /opt/airflow/dags/process_users_dag.py for tasks to queue
[2022-06-03 16:03:06,245] {logging_mixin.py:115} INFO - [2022-06-03 16:03:06,245] {dagbag.py:507} INFO - Filling up the DagBag from /opt/airflow/dags/process_users_dag.py
[2022-06-03 16:03:06,973] {logging_mixin.py:115} INFO - [2022-06-03 16:03:06,971] {dagbag.py:320} ERROR - Failed to import: /opt/airflow/dags/process_users_dag.py
Traceback (most recent call last):
  File "/home/airflow/.local/lib/python3.7/site-packages/airflow/models/dagbag.py", line 317, in parse
    loader.exec_module(new_module)
  File "<frozen importlib._bootstrap_external>", line 728, in exec_module
  File "<frozen importlib._bootstrap>", line 219, in _call_with_frames_removed
  File "/opt/airflow/dags/process_users_dag.py", line 13, in <module>
    USERS_JSON_FILENAME = Variable.get("users_json_filename")
  File "/home/airflow/.local/lib/python3.7/site-packages/airflow/models/variable.py", line 138, in get
    raise KeyError(f'Variable {key} does not exist')
KeyError: 'Variable users_json_filename does not exist'
[2022-06-03 16:03:06,973] {processor.py:653} WARNING - No viable dags retrieved from /opt/airflow/dags/process_users_dag.py
[2022-06-03 16:03:06,994] {processor.py:161} INFO - Processing /opt/airflow/dags/process_users_dag.py took 0.756 seconds
[2022-06-03 16:03:37,366] {processor.py:153} INFO - Started process (PID=3333) to work on /opt/airflow/dags/process_users_dag.py
[2022-06-03 16:03:37,373] {processor.py:641} INFO - Processing file /opt/airflow/dags/process_users_dag.py for tasks to queue
[2022-06-03 16:03:37,374] {logging_mixin.py:115} INFO - [2022-06-03 16:03:37,374] {dagbag.py:507} INFO - Filling up the DagBag from /opt/airflow/dags/process_users_dag.py
[2022-06-03 16:03:38,020] {logging_mixin.py:115} INFO - [2022-06-03 16:03:38,017] {dagbag.py:320} ERROR - Failed to import: /opt/airflow/dags/process_users_dag.py
Traceback (most recent call last):
  File "/home/airflow/.local/lib/python3.7/site-packages/airflow/models/dagbag.py", line 317, in parse
    loader.exec_module(new_module)
  File "<frozen importlib._bootstrap_external>", line 728, in exec_module
  File "<frozen importlib._bootstrap>", line 219, in _call_with_frames_removed
  File "/opt/airflow/dags/process_users_dag.py", line 13, in <module>
    USERS_JSON_FILENAME = Variable.get("users_json_filename")
  File "/home/airflow/.local/lib/python3.7/site-packages/airflow/models/variable.py", line 138, in get
    raise KeyError(f'Variable {key} does not exist')
KeyError: 'Variable users_json_filename does not exist'
[2022-06-03 16:03:38,020] {processor.py:653} WARNING - No viable dags retrieved from /opt/airflow/dags/process_users_dag.py
[2022-06-03 16:03:38,040] {processor.py:161} INFO - Processing /opt/airflow/dags/process_users_dag.py took 0.685 seconds
[2022-06-03 16:04:08,101] {processor.py:153} INFO - Started process (PID=3354) to work on /opt/airflow/dags/process_users_dag.py
[2022-06-03 16:04:08,102] {processor.py:641} INFO - Processing file /opt/airflow/dags/process_users_dag.py for tasks to queue
[2022-06-03 16:04:08,105] {logging_mixin.py:115} INFO - [2022-06-03 16:04:08,104] {dagbag.py:507} INFO - Filling up the DagBag from /opt/airflow/dags/process_users_dag.py
[2022-06-03 16:04:08,741] {logging_mixin.py:115} INFO - [2022-06-03 16:04:08,739] {dagbag.py:320} ERROR - Failed to import: /opt/airflow/dags/process_users_dag.py
Traceback (most recent call last):
  File "/home/airflow/.local/lib/python3.7/site-packages/airflow/models/dagbag.py", line 317, in parse
    loader.exec_module(new_module)
  File "<frozen importlib._bootstrap_external>", line 728, in exec_module
  File "<frozen importlib._bootstrap>", line 219, in _call_with_frames_removed
  File "/opt/airflow/dags/process_users_dag.py", line 13, in <module>
    USERS_JSON_FILENAME = Variable.get("users_json_filename")
  File "/home/airflow/.local/lib/python3.7/site-packages/airflow/models/variable.py", line 138, in get
    raise KeyError(f'Variable {key} does not exist')
KeyError: 'Variable users_json_filename does not exist'
[2022-06-03 16:04:08,742] {processor.py:653} WARNING - No viable dags retrieved from /opt/airflow/dags/process_users_dag.py
[2022-06-03 16:04:08,760] {processor.py:161} INFO - Processing /opt/airflow/dags/process_users_dag.py took 0.668 seconds
[2022-06-03 16:04:38,886] {processor.py:153} INFO - Started process (PID=3383) to work on /opt/airflow/dags/process_users_dag.py
[2022-06-03 16:04:38,887] {processor.py:641} INFO - Processing file /opt/airflow/dags/process_users_dag.py for tasks to queue
[2022-06-03 16:04:38,888] {logging_mixin.py:115} INFO - [2022-06-03 16:04:38,888] {dagbag.py:507} INFO - Filling up the DagBag from /opt/airflow/dags/process_users_dag.py
[2022-06-03 16:04:39,623] {logging_mixin.py:115} INFO - [2022-06-03 16:04:39,622] {dagbag.py:320} ERROR - Failed to import: /opt/airflow/dags/process_users_dag.py
Traceback (most recent call last):
  File "/home/airflow/.local/lib/python3.7/site-packages/airflow/models/dagbag.py", line 317, in parse
    loader.exec_module(new_module)
  File "<frozen importlib._bootstrap_external>", line 728, in exec_module
  File "<frozen importlib._bootstrap>", line 219, in _call_with_frames_removed
  File "/opt/airflow/dags/process_users_dag.py", line 13, in <module>
    USERS_JSON_FILENAME = Variable.get("users_json_filename")
  File "/home/airflow/.local/lib/python3.7/site-packages/airflow/models/variable.py", line 138, in get
    raise KeyError(f'Variable {key} does not exist')
KeyError: 'Variable users_json_filename does not exist'
[2022-06-03 16:04:39,624] {processor.py:653} WARNING - No viable dags retrieved from /opt/airflow/dags/process_users_dag.py
[2022-06-03 16:04:39,643] {processor.py:161} INFO - Processing /opt/airflow/dags/process_users_dag.py took 0.761 seconds
[2022-06-03 16:05:10,367] {processor.py:153} INFO - Started process (PID=3405) to work on /opt/airflow/dags/process_users_dag.py
[2022-06-03 16:05:10,369] {processor.py:641} INFO - Processing file /opt/airflow/dags/process_users_dag.py for tasks to queue
[2022-06-03 16:05:10,370] {logging_mixin.py:115} INFO - [2022-06-03 16:05:10,370] {dagbag.py:507} INFO - Filling up the DagBag from /opt/airflow/dags/process_users_dag.py
[2022-06-03 16:05:10,940] {logging_mixin.py:115} INFO - [2022-06-03 16:05:10,938] {dagbag.py:320} ERROR - Failed to import: /opt/airflow/dags/process_users_dag.py
Traceback (most recent call last):
  File "/home/airflow/.local/lib/python3.7/site-packages/airflow/models/dagbag.py", line 317, in parse
    loader.exec_module(new_module)
  File "<frozen importlib._bootstrap_external>", line 728, in exec_module
  File "<frozen importlib._bootstrap>", line 219, in _call_with_frames_removed
  File "/opt/airflow/dags/process_users_dag.py", line 13, in <module>
    USERS_JSON_FILENAME = Variable.get("users_json_filename")
  File "/home/airflow/.local/lib/python3.7/site-packages/airflow/models/variable.py", line 138, in get
    raise KeyError(f'Variable {key} does not exist')
KeyError: 'Variable users_json_filename does not exist'
[2022-06-03 16:05:10,940] {processor.py:653} WARNING - No viable dags retrieved from /opt/airflow/dags/process_users_dag.py
[2022-06-03 16:05:10,958] {processor.py:161} INFO - Processing /opt/airflow/dags/process_users_dag.py took 0.600 seconds
[2022-06-03 16:05:41,017] {processor.py:153} INFO - Started process (PID=3435) to work on /opt/airflow/dags/process_users_dag.py
[2022-06-03 16:05:41,018] {processor.py:641} INFO - Processing file /opt/airflow/dags/process_users_dag.py for tasks to queue
[2022-06-03 16:05:41,018] {logging_mixin.py:115} INFO - [2022-06-03 16:05:41,018] {dagbag.py:507} INFO - Filling up the DagBag from /opt/airflow/dags/process_users_dag.py
[2022-06-03 16:05:41,660] {logging_mixin.py:115} INFO - [2022-06-03 16:05:41,659] {dagbag.py:320} ERROR - Failed to import: /opt/airflow/dags/process_users_dag.py
Traceback (most recent call last):
  File "/home/airflow/.local/lib/python3.7/site-packages/airflow/models/dagbag.py", line 317, in parse
    loader.exec_module(new_module)
  File "<frozen importlib._bootstrap_external>", line 728, in exec_module
  File "<frozen importlib._bootstrap>", line 219, in _call_with_frames_removed
  File "/opt/airflow/dags/process_users_dag.py", line 13, in <module>
    USERS_JSON_FILENAME = Variable.get("users_json_filename")
  File "/home/airflow/.local/lib/python3.7/site-packages/airflow/models/variable.py", line 138, in get
    raise KeyError(f'Variable {key} does not exist')
KeyError: 'Variable users_json_filename does not exist'
[2022-06-03 16:05:41,660] {processor.py:653} WARNING - No viable dags retrieved from /opt/airflow/dags/process_users_dag.py
[2022-06-03 16:05:41,682] {processor.py:161} INFO - Processing /opt/airflow/dags/process_users_dag.py took 0.669 seconds
[2022-06-03 16:06:12,079] {processor.py:153} INFO - Started process (PID=3456) to work on /opt/airflow/dags/process_users_dag.py
[2022-06-03 16:06:12,080] {processor.py:641} INFO - Processing file /opt/airflow/dags/process_users_dag.py for tasks to queue
[2022-06-03 16:06:12,081] {logging_mixin.py:115} INFO - [2022-06-03 16:06:12,081] {dagbag.py:507} INFO - Filling up the DagBag from /opt/airflow/dags/process_users_dag.py
[2022-06-03 16:06:12,770] {logging_mixin.py:115} INFO - [2022-06-03 16:06:12,768] {dagbag.py:320} ERROR - Failed to import: /opt/airflow/dags/process_users_dag.py
Traceback (most recent call last):
  File "/home/airflow/.local/lib/python3.7/site-packages/airflow/models/dagbag.py", line 317, in parse
    loader.exec_module(new_module)
  File "<frozen importlib._bootstrap_external>", line 728, in exec_module
  File "<frozen importlib._bootstrap>", line 219, in _call_with_frames_removed
  File "/opt/airflow/dags/process_users_dag.py", line 13, in <module>
    USERS_JSON_FILENAME = Variable.get("users_json_filename")
  File "/home/airflow/.local/lib/python3.7/site-packages/airflow/models/variable.py", line 138, in get
    raise KeyError(f'Variable {key} does not exist')
KeyError: 'Variable users_json_filename does not exist'
[2022-06-03 16:06:12,770] {processor.py:653} WARNING - No viable dags retrieved from /opt/airflow/dags/process_users_dag.py
[2022-06-03 16:06:12,789] {processor.py:161} INFO - Processing /opt/airflow/dags/process_users_dag.py took 0.714 seconds
[2022-06-03 16:06:42,871] {processor.py:153} INFO - Started process (PID=3478) to work on /opt/airflow/dags/process_users_dag.py
[2022-06-03 16:06:42,878] {processor.py:641} INFO - Processing file /opt/airflow/dags/process_users_dag.py for tasks to queue
[2022-06-03 16:06:42,879] {logging_mixin.py:115} INFO - [2022-06-03 16:06:42,879] {dagbag.py:507} INFO - Filling up the DagBag from /opt/airflow/dags/process_users_dag.py
[2022-06-03 16:06:43,513] {logging_mixin.py:115} INFO - [2022-06-03 16:06:43,512] {dagbag.py:320} ERROR - Failed to import: /opt/airflow/dags/process_users_dag.py
Traceback (most recent call last):
  File "/home/airflow/.local/lib/python3.7/site-packages/airflow/models/dagbag.py", line 317, in parse
    loader.exec_module(new_module)
  File "<frozen importlib._bootstrap_external>", line 728, in exec_module
  File "<frozen importlib._bootstrap>", line 219, in _call_with_frames_removed
  File "/opt/airflow/dags/process_users_dag.py", line 13, in <module>
    USERS_JSON_FILENAME = Variable.get("users_json_filename")
  File "/home/airflow/.local/lib/python3.7/site-packages/airflow/models/variable.py", line 138, in get
    raise KeyError(f'Variable {key} does not exist')
KeyError: 'Variable users_json_filename does not exist'
[2022-06-03 16:06:43,513] {processor.py:653} WARNING - No viable dags retrieved from /opt/airflow/dags/process_users_dag.py
[2022-06-03 16:06:43,532] {processor.py:161} INFO - Processing /opt/airflow/dags/process_users_dag.py took 0.665 seconds
[2022-06-03 16:06:54,611] {processor.py:153} INFO - Started process (PID=3491) to work on /opt/airflow/dags/process_users_dag.py
[2022-06-03 16:06:54,613] {processor.py:641} INFO - Processing file /opt/airflow/dags/process_users_dag.py for tasks to queue
[2022-06-03 16:06:54,615] {logging_mixin.py:115} INFO - [2022-06-03 16:06:54,615] {dagbag.py:507} INFO - Filling up the DagBag from /opt/airflow/dags/process_users_dag.py
[2022-06-03 16:06:55,277] {logging_mixin.py:115} INFO - [2022-06-03 16:06:55,276] {dagbag.py:320} ERROR - Failed to import: /opt/airflow/dags/process_users_dag.py
Traceback (most recent call last):
  File "/home/airflow/.local/lib/python3.7/site-packages/airflow/models/dagbag.py", line 317, in parse
    loader.exec_module(new_module)
  File "<frozen importlib._bootstrap_external>", line 728, in exec_module
  File "<frozen importlib._bootstrap>", line 219, in _call_with_frames_removed
  File "/opt/airflow/dags/process_users_dag.py", line 13, in <module>
    USERS_JSON_FILENAME = Variable.get("users_json_filename")
  File "/home/airflow/.local/lib/python3.7/site-packages/airflow/models/variable.py", line 138, in get
    raise KeyError(f'Variable {key} does not exist')
KeyError: 'Variable users_json_filename does not exist'
[2022-06-03 16:06:55,277] {processor.py:653} WARNING - No viable dags retrieved from /opt/airflow/dags/process_users_dag.py
[2022-06-03 16:06:55,289] {processor.py:161} INFO - Processing /opt/airflow/dags/process_users_dag.py took 0.691 seconds
[2022-06-03 16:07:25,963] {processor.py:153} INFO - Started process (PID=3521) to work on /opt/airflow/dags/process_users_dag.py
[2022-06-03 16:07:25,969] {processor.py:641} INFO - Processing file /opt/airflow/dags/process_users_dag.py for tasks to queue
[2022-06-03 16:07:25,970] {logging_mixin.py:115} INFO - [2022-06-03 16:07:25,970] {dagbag.py:507} INFO - Filling up the DagBag from /opt/airflow/dags/process_users_dag.py
[2022-06-03 16:07:26,595] {logging_mixin.py:115} INFO - [2022-06-03 16:07:26,593] {dagbag.py:320} ERROR - Failed to import: /opt/airflow/dags/process_users_dag.py
Traceback (most recent call last):
  File "/home/airflow/.local/lib/python3.7/site-packages/airflow/models/dagbag.py", line 317, in parse
    loader.exec_module(new_module)
  File "<frozen importlib._bootstrap_external>", line 728, in exec_module
  File "<frozen importlib._bootstrap>", line 219, in _call_with_frames_removed
  File "/opt/airflow/dags/process_users_dag.py", line 13, in <module>
    USERS_JSON_FILENAME = Variable.get("users_json_filename")
  File "/home/airflow/.local/lib/python3.7/site-packages/airflow/models/variable.py", line 138, in get
    raise KeyError(f'Variable {key} does not exist')
KeyError: 'Variable users_json_filename does not exist'
[2022-06-03 16:07:26,595] {processor.py:653} WARNING - No viable dags retrieved from /opt/airflow/dags/process_users_dag.py
[2022-06-03 16:07:26,616] {processor.py:161} INFO - Processing /opt/airflow/dags/process_users_dag.py took 0.656 seconds
[2022-06-03 16:07:57,346] {processor.py:153} INFO - Started process (PID=3542) to work on /opt/airflow/dags/process_users_dag.py
[2022-06-03 16:07:57,347] {processor.py:641} INFO - Processing file /opt/airflow/dags/process_users_dag.py for tasks to queue
[2022-06-03 16:07:57,348] {logging_mixin.py:115} INFO - [2022-06-03 16:07:57,348] {dagbag.py:507} INFO - Filling up the DagBag from /opt/airflow/dags/process_users_dag.py
[2022-06-03 16:07:57,922] {logging_mixin.py:115} INFO - [2022-06-03 16:07:57,921] {dagbag.py:320} ERROR - Failed to import: /opt/airflow/dags/process_users_dag.py
Traceback (most recent call last):
  File "/home/airflow/.local/lib/python3.7/site-packages/airflow/models/dagbag.py", line 317, in parse
    loader.exec_module(new_module)
  File "<frozen importlib._bootstrap_external>", line 728, in exec_module
  File "<frozen importlib._bootstrap>", line 219, in _call_with_frames_removed
  File "/opt/airflow/dags/process_users_dag.py", line 13, in <module>
    USERS_JSON_FILENAME = Variable.get("users_json_filename")
  File "/home/airflow/.local/lib/python3.7/site-packages/airflow/models/variable.py", line 138, in get
    raise KeyError(f'Variable {key} does not exist')
KeyError: 'Variable users_json_filename does not exist'
[2022-06-03 16:07:57,923] {processor.py:653} WARNING - No viable dags retrieved from /opt/airflow/dags/process_users_dag.py
[2022-06-03 16:07:57,941] {processor.py:161} INFO - Processing /opt/airflow/dags/process_users_dag.py took 0.600 seconds
[2022-06-03 16:08:28,027] {processor.py:153} INFO - Started process (PID=3572) to work on /opt/airflow/dags/process_users_dag.py
[2022-06-03 16:08:28,028] {processor.py:641} INFO - Processing file /opt/airflow/dags/process_users_dag.py for tasks to queue
[2022-06-03 16:08:28,030] {logging_mixin.py:115} INFO - [2022-06-03 16:08:28,029] {dagbag.py:507} INFO - Filling up the DagBag from /opt/airflow/dags/process_users_dag.py
[2022-06-03 16:08:28,629] {logging_mixin.py:115} INFO - [2022-06-03 16:08:28,628] {dagbag.py:320} ERROR - Failed to import: /opt/airflow/dags/process_users_dag.py
Traceback (most recent call last):
  File "/home/airflow/.local/lib/python3.7/site-packages/airflow/models/dagbag.py", line 317, in parse
    loader.exec_module(new_module)
  File "<frozen importlib._bootstrap_external>", line 728, in exec_module
  File "<frozen importlib._bootstrap>", line 219, in _call_with_frames_removed
  File "/opt/airflow/dags/process_users_dag.py", line 13, in <module>
    USERS_JSON_FILENAME = Variable.get("users_json_filename")
  File "/home/airflow/.local/lib/python3.7/site-packages/airflow/models/variable.py", line 138, in get
    raise KeyError(f'Variable {key} does not exist')
KeyError: 'Variable users_json_filename does not exist'
[2022-06-03 16:08:28,629] {processor.py:653} WARNING - No viable dags retrieved from /opt/airflow/dags/process_users_dag.py
[2022-06-03 16:08:28,650] {processor.py:161} INFO - Processing /opt/airflow/dags/process_users_dag.py took 0.634 seconds
[2022-06-03 16:08:59,108] {processor.py:153} INFO - Started process (PID=3594) to work on /opt/airflow/dags/process_users_dag.py
[2022-06-03 16:08:59,108] {processor.py:641} INFO - Processing file /opt/airflow/dags/process_users_dag.py for tasks to queue
[2022-06-03 16:08:59,109] {logging_mixin.py:115} INFO - [2022-06-03 16:08:59,109] {dagbag.py:507} INFO - Filling up the DagBag from /opt/airflow/dags/process_users_dag.py
[2022-06-03 16:08:59,709] {logging_mixin.py:115} INFO - [2022-06-03 16:08:59,707] {dagbag.py:320} ERROR - Failed to import: /opt/airflow/dags/process_users_dag.py
Traceback (most recent call last):
  File "/home/airflow/.local/lib/python3.7/site-packages/airflow/models/dagbag.py", line 317, in parse
    loader.exec_module(new_module)
  File "<frozen importlib._bootstrap_external>", line 728, in exec_module
  File "<frozen importlib._bootstrap>", line 219, in _call_with_frames_removed
  File "/opt/airflow/dags/process_users_dag.py", line 13, in <module>
    USERS_JSON_FILENAME = Variable.get("users_json_filename")
  File "/home/airflow/.local/lib/python3.7/site-packages/airflow/models/variable.py", line 138, in get
    raise KeyError(f'Variable {key} does not exist')
KeyError: 'Variable users_json_filename does not exist'
[2022-06-03 16:08:59,709] {processor.py:653} WARNING - No viable dags retrieved from /opt/airflow/dags/process_users_dag.py
[2022-06-03 16:08:59,727] {processor.py:161} INFO - Processing /opt/airflow/dags/process_users_dag.py took 0.625 seconds
[2022-06-03 16:09:29,830] {processor.py:153} INFO - Started process (PID=3624) to work on /opt/airflow/dags/process_users_dag.py
[2022-06-03 16:09:29,830] {processor.py:641} INFO - Processing file /opt/airflow/dags/process_users_dag.py for tasks to queue
[2022-06-03 16:09:29,831] {logging_mixin.py:115} INFO - [2022-06-03 16:09:29,831] {dagbag.py:507} INFO - Filling up the DagBag from /opt/airflow/dags/process_users_dag.py
[2022-06-03 16:09:30,501] {logging_mixin.py:115} INFO - [2022-06-03 16:09:30,500] {dagbag.py:320} ERROR - Failed to import: /opt/airflow/dags/process_users_dag.py
Traceback (most recent call last):
  File "/home/airflow/.local/lib/python3.7/site-packages/airflow/models/dagbag.py", line 317, in parse
    loader.exec_module(new_module)
  File "<frozen importlib._bootstrap_external>", line 728, in exec_module
  File "<frozen importlib._bootstrap>", line 219, in _call_with_frames_removed
  File "/opt/airflow/dags/process_users_dag.py", line 13, in <module>
    USERS_JSON_FILENAME = Variable.get("users_json_filename")
  File "/home/airflow/.local/lib/python3.7/site-packages/airflow/models/variable.py", line 138, in get
    raise KeyError(f'Variable {key} does not exist')
KeyError: 'Variable users_json_filename does not exist'
[2022-06-03 16:09:30,501] {processor.py:653} WARNING - No viable dags retrieved from /opt/airflow/dags/process_users_dag.py
[2022-06-03 16:09:30,520] {processor.py:161} INFO - Processing /opt/airflow/dags/process_users_dag.py took 0.696 seconds
[2022-06-03 16:10:00,898] {processor.py:153} INFO - Started process (PID=3645) to work on /opt/airflow/dags/process_users_dag.py
[2022-06-03 16:10:00,905] {processor.py:641} INFO - Processing file /opt/airflow/dags/process_users_dag.py for tasks to queue
[2022-06-03 16:10:00,907] {logging_mixin.py:115} INFO - [2022-06-03 16:10:00,906] {dagbag.py:507} INFO - Filling up the DagBag from /opt/airflow/dags/process_users_dag.py
[2022-06-03 16:10:01,653] {logging_mixin.py:115} INFO - [2022-06-03 16:10:01,651] {dagbag.py:320} ERROR - Failed to import: /opt/airflow/dags/process_users_dag.py
Traceback (most recent call last):
  File "/home/airflow/.local/lib/python3.7/site-packages/airflow/models/dagbag.py", line 317, in parse
    loader.exec_module(new_module)
  File "<frozen importlib._bootstrap_external>", line 728, in exec_module
  File "<frozen importlib._bootstrap>", line 219, in _call_with_frames_removed
  File "/opt/airflow/dags/process_users_dag.py", line 13, in <module>
    USERS_JSON_FILENAME = Variable.get("users_json_filename")
  File "/home/airflow/.local/lib/python3.7/site-packages/airflow/models/variable.py", line 138, in get
    raise KeyError(f'Variable {key} does not exist')
KeyError: 'Variable users_json_filename does not exist'
[2022-06-03 16:10:01,653] {processor.py:653} WARNING - No viable dags retrieved from /opt/airflow/dags/process_users_dag.py
[2022-06-03 16:10:01,671] {processor.py:161} INFO - Processing /opt/airflow/dags/process_users_dag.py took 0.777 seconds
[2022-06-03 16:10:24,742] {processor.py:153} INFO - Started process (PID=3666) to work on /opt/airflow/dags/process_users_dag.py
[2022-06-03 16:10:24,743] {processor.py:641} INFO - Processing file /opt/airflow/dags/process_users_dag.py for tasks to queue
[2022-06-03 16:10:24,744] {logging_mixin.py:115} INFO - [2022-06-03 16:10:24,744] {dagbag.py:507} INFO - Filling up the DagBag from /opt/airflow/dags/process_users_dag.py
[2022-06-03 16:10:25,450] {logging_mixin.py:115} INFO - [2022-06-03 16:10:25,449] {dagbag.py:320} ERROR - Failed to import: /opt/airflow/dags/process_users_dag.py
Traceback (most recent call last):
  File "/home/airflow/.local/lib/python3.7/site-packages/airflow/models/dagbag.py", line 317, in parse
    loader.exec_module(new_module)
  File "<frozen importlib._bootstrap_external>", line 728, in exec_module
  File "<frozen importlib._bootstrap>", line 219, in _call_with_frames_removed
  File "/opt/airflow/dags/process_users_dag.py", line 13, in <module>
    USERS_JSON_FILENAME = Variable.get("users_json_filename")
  File "/home/airflow/.local/lib/python3.7/site-packages/airflow/models/variable.py", line 138, in get
    raise KeyError(f'Variable {key} does not exist')
KeyError: 'Variable users_json_filename does not exist'
[2022-06-03 16:10:25,450] {processor.py:653} WARNING - No viable dags retrieved from /opt/airflow/dags/process_users_dag.py
[2022-06-03 16:10:25,462] {processor.py:161} INFO - Processing /opt/airflow/dags/process_users_dag.py took 0.723 seconds
[2022-06-03 16:10:55,576] {processor.py:153} INFO - Started process (PID=3687) to work on /opt/airflow/dags/process_users_dag.py
[2022-06-03 16:10:55,583] {processor.py:641} INFO - Processing file /opt/airflow/dags/process_users_dag.py for tasks to queue
[2022-06-03 16:10:55,585] {logging_mixin.py:115} INFO - [2022-06-03 16:10:55,585] {dagbag.py:507} INFO - Filling up the DagBag from /opt/airflow/dags/process_users_dag.py
[2022-06-03 16:10:56,285] {logging_mixin.py:115} INFO - [2022-06-03 16:10:56,284] {dagbag.py:320} ERROR - Failed to import: /opt/airflow/dags/process_users_dag.py
Traceback (most recent call last):
  File "/home/airflow/.local/lib/python3.7/site-packages/airflow/models/dagbag.py", line 317, in parse
    loader.exec_module(new_module)
  File "<frozen importlib._bootstrap_external>", line 728, in exec_module
  File "<frozen importlib._bootstrap>", line 219, in _call_with_frames_removed
  File "/opt/airflow/dags/process_users_dag.py", line 13, in <module>
    USERS_JSON_FILENAME = Variable.get("users_json_filename")
  File "/home/airflow/.local/lib/python3.7/site-packages/airflow/models/variable.py", line 138, in get
    raise KeyError(f'Variable {key} does not exist')
KeyError: 'Variable users_json_filename does not exist'
[2022-06-03 16:10:56,286] {processor.py:653} WARNING - No viable dags retrieved from /opt/airflow/dags/process_users_dag.py
[2022-06-03 16:10:56,310] {processor.py:161} INFO - Processing /opt/airflow/dags/process_users_dag.py took 0.748 seconds
[2022-06-03 16:11:20,222] {processor.py:153} INFO - Started process (PID=3708) to work on /opt/airflow/dags/process_users_dag.py
[2022-06-03 16:11:20,223] {processor.py:641} INFO - Processing file /opt/airflow/dags/process_users_dag.py for tasks to queue
[2022-06-03 16:11:20,226] {logging_mixin.py:115} INFO - [2022-06-03 16:11:20,225] {dagbag.py:507} INFO - Filling up the DagBag from /opt/airflow/dags/process_users_dag.py
[2022-06-03 16:11:21,262] {logging_mixin.py:115} INFO - [2022-06-03 16:11:21,260] {dagbag.py:320} ERROR - Failed to import: /opt/airflow/dags/process_users_dag.py
Traceback (most recent call last):
  File "/home/airflow/.local/lib/python3.7/site-packages/airflow/models/dagbag.py", line 317, in parse
    loader.exec_module(new_module)
  File "<frozen importlib._bootstrap_external>", line 728, in exec_module
  File "<frozen importlib._bootstrap>", line 219, in _call_with_frames_removed
  File "/opt/airflow/dags/process_users_dag.py", line 13, in <module>
    USERS_JSON_FILENAME = Variable.get("users_json_filename")
  File "/home/airflow/.local/lib/python3.7/site-packages/airflow/models/variable.py", line 138, in get
    raise KeyError(f'Variable {key} does not exist')
KeyError: 'Variable users_json_filename does not exist'
[2022-06-03 16:11:21,263] {processor.py:653} WARNING - No viable dags retrieved from /opt/airflow/dags/process_users_dag.py
[2022-06-03 16:11:21,277] {processor.py:161} INFO - Processing /opt/airflow/dags/process_users_dag.py took 1.064 seconds
[2022-06-03 16:11:48,296] {processor.py:153} INFO - Started process (PID=3737) to work on /opt/airflow/dags/process_users_dag.py
[2022-06-03 16:11:48,303] {processor.py:641} INFO - Processing file /opt/airflow/dags/process_users_dag.py for tasks to queue
[2022-06-03 16:11:48,304] {logging_mixin.py:115} INFO - [2022-06-03 16:11:48,303] {dagbag.py:507} INFO - Filling up the DagBag from /opt/airflow/dags/process_users_dag.py
[2022-06-03 16:11:48,306] {logging_mixin.py:115} INFO - [2022-06-03 16:11:48,305] {dagbag.py:320} ERROR - Failed to import: /opt/airflow/dags/process_users_dag.py
Traceback (most recent call last):
  File "/home/airflow/.local/lib/python3.7/site-packages/airflow/models/dagbag.py", line 317, in parse
    loader.exec_module(new_module)
  File "<frozen importlib._bootstrap_external>", line 724, in exec_module
  File "<frozen importlib._bootstrap_external>", line 860, in get_code
  File "<frozen importlib._bootstrap_external>", line 791, in source_to_code
  File "<frozen importlib._bootstrap>", line 219, in _call_with_frames_removed
  File "/opt/airflow/dags/process_users_dag.py", line 42
    [get_users_from_csv(), _get_users_from_postgress]
                                                      ^
IndentationError: unindent does not match any outer indentation level
[2022-06-03 16:11:48,307] {processor.py:653} WARNING - No viable dags retrieved from /opt/airflow/dags/process_users_dag.py
[2022-06-03 16:11:48,350] {processor.py:161} INFO - Processing /opt/airflow/dags/process_users_dag.py took 0.058 seconds
[2022-06-03 16:12:18,462] {processor.py:153} INFO - Started process (PID=3758) to work on /opt/airflow/dags/process_users_dag.py
[2022-06-03 16:12:18,463] {processor.py:641} INFO - Processing file /opt/airflow/dags/process_users_dag.py for tasks to queue
[2022-06-03 16:12:18,463] {logging_mixin.py:115} INFO - [2022-06-03 16:12:18,463] {dagbag.py:507} INFO - Filling up the DagBag from /opt/airflow/dags/process_users_dag.py
[2022-06-03 16:12:18,467] {logging_mixin.py:115} INFO - [2022-06-03 16:12:18,466] {dagbag.py:320} ERROR - Failed to import: /opt/airflow/dags/process_users_dag.py
Traceback (most recent call last):
  File "/home/airflow/.local/lib/python3.7/site-packages/airflow/models/dagbag.py", line 317, in parse
    loader.exec_module(new_module)
  File "<frozen importlib._bootstrap_external>", line 724, in exec_module
  File "<frozen importlib._bootstrap_external>", line 860, in get_code
  File "<frozen importlib._bootstrap_external>", line 791, in source_to_code
  File "<frozen importlib._bootstrap>", line 219, in _call_with_frames_removed
  File "/opt/airflow/dags/process_users_dag.py", line 42
    [get_users_from_csv(), _get_users_from_postgress]
                                                      ^
IndentationError: unindent does not match any outer indentation level
[2022-06-03 16:12:18,467] {processor.py:653} WARNING - No viable dags retrieved from /opt/airflow/dags/process_users_dag.py
[2022-06-03 16:12:18,494] {processor.py:161} INFO - Processing /opt/airflow/dags/process_users_dag.py took 0.037 seconds
[2022-06-03 16:12:48,582] {processor.py:153} INFO - Started process (PID=3787) to work on /opt/airflow/dags/process_users_dag.py
[2022-06-03 16:12:48,588] {processor.py:641} INFO - Processing file /opt/airflow/dags/process_users_dag.py for tasks to queue
[2022-06-03 16:12:48,589] {logging_mixin.py:115} INFO - [2022-06-03 16:12:48,589] {dagbag.py:507} INFO - Filling up the DagBag from /opt/airflow/dags/process_users_dag.py
[2022-06-03 16:12:48,592] {logging_mixin.py:115} INFO - [2022-06-03 16:12:48,591] {dagbag.py:320} ERROR - Failed to import: /opt/airflow/dags/process_users_dag.py
Traceback (most recent call last):
  File "/home/airflow/.local/lib/python3.7/site-packages/airflow/models/dagbag.py", line 317, in parse
    loader.exec_module(new_module)
  File "<frozen importlib._bootstrap_external>", line 724, in exec_module
  File "<frozen importlib._bootstrap_external>", line 860, in get_code
  File "<frozen importlib._bootstrap_external>", line 791, in source_to_code
  File "<frozen importlib._bootstrap>", line 219, in _call_with_frames_removed
  File "/opt/airflow/dags/process_users_dag.py", line 42
    [get_users_from_csv(), _get_users_from_postgress]
                                                      ^
IndentationError: unindent does not match any outer indentation level
[2022-06-03 16:12:48,592] {processor.py:653} WARNING - No viable dags retrieved from /opt/airflow/dags/process_users_dag.py
[2022-06-03 16:12:48,626] {processor.py:161} INFO - Processing /opt/airflow/dags/process_users_dag.py took 0.048 seconds
[2022-06-03 16:13:18,739] {processor.py:153} INFO - Started process (PID=3807) to work on /opt/airflow/dags/process_users_dag.py
[2022-06-03 16:13:18,740] {processor.py:641} INFO - Processing file /opt/airflow/dags/process_users_dag.py for tasks to queue
[2022-06-03 16:13:18,742] {logging_mixin.py:115} INFO - [2022-06-03 16:13:18,742] {dagbag.py:507} INFO - Filling up the DagBag from /opt/airflow/dags/process_users_dag.py
[2022-06-03 16:13:18,750] {logging_mixin.py:115} INFO - [2022-06-03 16:13:18,748] {dagbag.py:320} ERROR - Failed to import: /opt/airflow/dags/process_users_dag.py
Traceback (most recent call last):
  File "/home/airflow/.local/lib/python3.7/site-packages/airflow/models/dagbag.py", line 317, in parse
    loader.exec_module(new_module)
  File "<frozen importlib._bootstrap_external>", line 724, in exec_module
  File "<frozen importlib._bootstrap_external>", line 860, in get_code
  File "<frozen importlib._bootstrap_external>", line 791, in source_to_code
  File "<frozen importlib._bootstrap>", line 219, in _call_with_frames_removed
  File "/opt/airflow/dags/process_users_dag.py", line 42
    [get_users_from_csv(), _get_users_from_postgress]
                                                      ^
IndentationError: unindent does not match any outer indentation level
[2022-06-03 16:13:18,752] {processor.py:653} WARNING - No viable dags retrieved from /opt/airflow/dags/process_users_dag.py
[2022-06-03 16:13:18,826] {processor.py:161} INFO - Processing /opt/airflow/dags/process_users_dag.py took 0.099 seconds
[2022-06-03 16:13:48,927] {processor.py:153} INFO - Started process (PID=3826) to work on /opt/airflow/dags/process_users_dag.py
[2022-06-03 16:13:48,927] {processor.py:641} INFO - Processing file /opt/airflow/dags/process_users_dag.py for tasks to queue
[2022-06-03 16:13:48,928] {logging_mixin.py:115} INFO - [2022-06-03 16:13:48,928] {dagbag.py:507} INFO - Filling up the DagBag from /opt/airflow/dags/process_users_dag.py
[2022-06-03 16:13:48,930] {logging_mixin.py:115} INFO - [2022-06-03 16:13:48,929] {dagbag.py:320} ERROR - Failed to import: /opt/airflow/dags/process_users_dag.py
Traceback (most recent call last):
  File "/home/airflow/.local/lib/python3.7/site-packages/airflow/models/dagbag.py", line 317, in parse
    loader.exec_module(new_module)
  File "<frozen importlib._bootstrap_external>", line 724, in exec_module
  File "<frozen importlib._bootstrap_external>", line 860, in get_code
  File "<frozen importlib._bootstrap_external>", line 791, in source_to_code
  File "<frozen importlib._bootstrap>", line 219, in _call_with_frames_removed
  File "/opt/airflow/dags/process_users_dag.py", line 42
    [get_users_from_csv(), _get_users_from_postgress]
                                                      ^
IndentationError: unindent does not match any outer indentation level
[2022-06-03 16:13:48,930] {processor.py:653} WARNING - No viable dags retrieved from /opt/airflow/dags/process_users_dag.py
[2022-06-03 16:13:48,963] {processor.py:161} INFO - Processing /opt/airflow/dags/process_users_dag.py took 0.041 seconds
[2022-06-03 16:14:19,055] {processor.py:153} INFO - Started process (PID=3856) to work on /opt/airflow/dags/process_users_dag.py
[2022-06-03 16:14:19,055] {processor.py:641} INFO - Processing file /opt/airflow/dags/process_users_dag.py for tasks to queue
[2022-06-03 16:14:19,056] {logging_mixin.py:115} INFO - [2022-06-03 16:14:19,056] {dagbag.py:507} INFO - Filling up the DagBag from /opt/airflow/dags/process_users_dag.py
[2022-06-03 16:14:19,058] {logging_mixin.py:115} INFO - [2022-06-03 16:14:19,057] {dagbag.py:320} ERROR - Failed to import: /opt/airflow/dags/process_users_dag.py
Traceback (most recent call last):
  File "/home/airflow/.local/lib/python3.7/site-packages/airflow/models/dagbag.py", line 317, in parse
    loader.exec_module(new_module)
  File "<frozen importlib._bootstrap_external>", line 724, in exec_module
  File "<frozen importlib._bootstrap_external>", line 860, in get_code
  File "<frozen importlib._bootstrap_external>", line 791, in source_to_code
  File "<frozen importlib._bootstrap>", line 219, in _call_with_frames_removed
  File "/opt/airflow/dags/process_users_dag.py", line 42
    [get_users_from_csv(), _get_users_from_postgress]
                                                      ^
IndentationError: unindent does not match any outer indentation level
[2022-06-03 16:14:19,059] {processor.py:653} WARNING - No viable dags retrieved from /opt/airflow/dags/process_users_dag.py
[2022-06-03 16:14:19,088] {processor.py:161} INFO - Processing /opt/airflow/dags/process_users_dag.py took 0.039 seconds
[2022-06-03 16:14:49,178] {processor.py:153} INFO - Started process (PID=3876) to work on /opt/airflow/dags/process_users_dag.py
[2022-06-03 16:14:49,185] {processor.py:641} INFO - Processing file /opt/airflow/dags/process_users_dag.py for tasks to queue
[2022-06-03 16:14:49,186] {logging_mixin.py:115} INFO - [2022-06-03 16:14:49,186] {dagbag.py:507} INFO - Filling up the DagBag from /opt/airflow/dags/process_users_dag.py
[2022-06-03 16:14:49,188] {logging_mixin.py:115} INFO - [2022-06-03 16:14:49,187] {dagbag.py:320} ERROR - Failed to import: /opt/airflow/dags/process_users_dag.py
Traceback (most recent call last):
  File "/home/airflow/.local/lib/python3.7/site-packages/airflow/models/dagbag.py", line 317, in parse
    loader.exec_module(new_module)
  File "<frozen importlib._bootstrap_external>", line 724, in exec_module
  File "<frozen importlib._bootstrap_external>", line 860, in get_code
  File "<frozen importlib._bootstrap_external>", line 791, in source_to_code
  File "<frozen importlib._bootstrap>", line 219, in _call_with_frames_removed
  File "/opt/airflow/dags/process_users_dag.py", line 42
    [get_users_from_csv(), _get_users_from_postgress]
                                                      ^
IndentationError: unindent does not match any outer indentation level
[2022-06-03 16:14:49,189] {processor.py:653} WARNING - No viable dags retrieved from /opt/airflow/dags/process_users_dag.py
[2022-06-03 16:14:49,217] {processor.py:161} INFO - Processing /opt/airflow/dags/process_users_dag.py took 0.042 seconds
[2022-06-03 16:15:19,308] {processor.py:153} INFO - Started process (PID=3906) to work on /opt/airflow/dags/process_users_dag.py
[2022-06-03 16:15:19,309] {processor.py:641} INFO - Processing file /opt/airflow/dags/process_users_dag.py for tasks to queue
[2022-06-03 16:15:19,310] {logging_mixin.py:115} INFO - [2022-06-03 16:15:19,310] {dagbag.py:507} INFO - Filling up the DagBag from /opt/airflow/dags/process_users_dag.py
[2022-06-03 16:15:19,313] {logging_mixin.py:115} INFO - [2022-06-03 16:15:19,312] {dagbag.py:320} ERROR - Failed to import: /opt/airflow/dags/process_users_dag.py
Traceback (most recent call last):
  File "/home/airflow/.local/lib/python3.7/site-packages/airflow/models/dagbag.py", line 317, in parse
    loader.exec_module(new_module)
  File "<frozen importlib._bootstrap_external>", line 724, in exec_module
  File "<frozen importlib._bootstrap_external>", line 860, in get_code
  File "<frozen importlib._bootstrap_external>", line 791, in source_to_code
  File "<frozen importlib._bootstrap>", line 219, in _call_with_frames_removed
  File "/opt/airflow/dags/process_users_dag.py", line 42
    [get_users_from_csv(), _get_users_from_postgress]
                                                      ^
IndentationError: unindent does not match any outer indentation level
[2022-06-03 16:15:19,313] {processor.py:653} WARNING - No viable dags retrieved from /opt/airflow/dags/process_users_dag.py
[2022-06-03 16:15:19,349] {processor.py:161} INFO - Processing /opt/airflow/dags/process_users_dag.py took 0.047 seconds
[2022-06-03 16:15:49,442] {processor.py:153} INFO - Started process (PID=3925) to work on /opt/airflow/dags/process_users_dag.py
[2022-06-03 16:15:49,449] {processor.py:641} INFO - Processing file /opt/airflow/dags/process_users_dag.py for tasks to queue
[2022-06-03 16:15:49,450] {logging_mixin.py:115} INFO - [2022-06-03 16:15:49,450] {dagbag.py:507} INFO - Filling up the DagBag from /opt/airflow/dags/process_users_dag.py
[2022-06-03 16:15:49,455] {logging_mixin.py:115} INFO - [2022-06-03 16:15:49,453] {dagbag.py:320} ERROR - Failed to import: /opt/airflow/dags/process_users_dag.py
Traceback (most recent call last):
  File "/home/airflow/.local/lib/python3.7/site-packages/airflow/models/dagbag.py", line 317, in parse
    loader.exec_module(new_module)
  File "<frozen importlib._bootstrap_external>", line 724, in exec_module
  File "<frozen importlib._bootstrap_external>", line 860, in get_code
  File "<frozen importlib._bootstrap_external>", line 791, in source_to_code
  File "<frozen importlib._bootstrap>", line 219, in _call_with_frames_removed
  File "/opt/airflow/dags/process_users_dag.py", line 42
    [get_users_from_csv(), _get_users_from_postgress]
                                                      ^
IndentationError: unindent does not match any outer indentation level
[2022-06-03 16:15:49,456] {processor.py:653} WARNING - No viable dags retrieved from /opt/airflow/dags/process_users_dag.py
[2022-06-03 16:15:49,506] {processor.py:161} INFO - Processing /opt/airflow/dags/process_users_dag.py took 0.072 seconds
[2022-06-03 16:16:19,592] {processor.py:153} INFO - Started process (PID=3945) to work on /opt/airflow/dags/process_users_dag.py
[2022-06-03 16:16:19,593] {processor.py:641} INFO - Processing file /opt/airflow/dags/process_users_dag.py for tasks to queue
[2022-06-03 16:16:19,594] {logging_mixin.py:115} INFO - [2022-06-03 16:16:19,594] {dagbag.py:507} INFO - Filling up the DagBag from /opt/airflow/dags/process_users_dag.py
[2022-06-03 16:16:19,597] {logging_mixin.py:115} INFO - [2022-06-03 16:16:19,596] {dagbag.py:320} ERROR - Failed to import: /opt/airflow/dags/process_users_dag.py
Traceback (most recent call last):
  File "/home/airflow/.local/lib/python3.7/site-packages/airflow/models/dagbag.py", line 317, in parse
    loader.exec_module(new_module)
  File "<frozen importlib._bootstrap_external>", line 724, in exec_module
  File "<frozen importlib._bootstrap_external>", line 860, in get_code
  File "<frozen importlib._bootstrap_external>", line 791, in source_to_code
  File "<frozen importlib._bootstrap>", line 219, in _call_with_frames_removed
  File "/opt/airflow/dags/process_users_dag.py", line 42
    [get_users_from_csv(), _get_users_from_postgress]
                                                      ^
IndentationError: unindent does not match any outer indentation level
[2022-06-03 16:16:19,598] {processor.py:653} WARNING - No viable dags retrieved from /opt/airflow/dags/process_users_dag.py
[2022-06-03 16:16:19,627] {processor.py:161} INFO - Processing /opt/airflow/dags/process_users_dag.py took 0.040 seconds
[2022-06-03 16:16:49,726] {processor.py:153} INFO - Started process (PID=3973) to work on /opt/airflow/dags/process_users_dag.py
[2022-06-03 16:16:49,727] {processor.py:641} INFO - Processing file /opt/airflow/dags/process_users_dag.py for tasks to queue
[2022-06-03 16:16:49,728] {logging_mixin.py:115} INFO - [2022-06-03 16:16:49,728] {dagbag.py:507} INFO - Filling up the DagBag from /opt/airflow/dags/process_users_dag.py
[2022-06-03 16:16:49,731] {logging_mixin.py:115} INFO - [2022-06-03 16:16:49,730] {dagbag.py:320} ERROR - Failed to import: /opt/airflow/dags/process_users_dag.py
Traceback (most recent call last):
  File "/home/airflow/.local/lib/python3.7/site-packages/airflow/models/dagbag.py", line 317, in parse
    loader.exec_module(new_module)
  File "<frozen importlib._bootstrap_external>", line 724, in exec_module
  File "<frozen importlib._bootstrap_external>", line 860, in get_code
  File "<frozen importlib._bootstrap_external>", line 791, in source_to_code
  File "<frozen importlib._bootstrap>", line 219, in _call_with_frames_removed
  File "/opt/airflow/dags/process_users_dag.py", line 42
    [get_users_from_csv(), _get_users_from_postgress]
                                                      ^
IndentationError: unindent does not match any outer indentation level
[2022-06-03 16:16:49,731] {processor.py:653} WARNING - No viable dags retrieved from /opt/airflow/dags/process_users_dag.py
[2022-06-03 16:16:49,774] {processor.py:161} INFO - Processing /opt/airflow/dags/process_users_dag.py took 0.055 seconds
[2022-06-03 16:17:19,853] {processor.py:153} INFO - Started process (PID=3993) to work on /opt/airflow/dags/process_users_dag.py
[2022-06-03 16:17:19,854] {processor.py:641} INFO - Processing file /opt/airflow/dags/process_users_dag.py for tasks to queue
[2022-06-03 16:17:19,855] {logging_mixin.py:115} INFO - [2022-06-03 16:17:19,854] {dagbag.py:507} INFO - Filling up the DagBag from /opt/airflow/dags/process_users_dag.py
[2022-06-03 16:17:19,857] {logging_mixin.py:115} INFO - [2022-06-03 16:17:19,856] {dagbag.py:320} ERROR - Failed to import: /opt/airflow/dags/process_users_dag.py
Traceback (most recent call last):
  File "/home/airflow/.local/lib/python3.7/site-packages/airflow/models/dagbag.py", line 317, in parse
    loader.exec_module(new_module)
  File "<frozen importlib._bootstrap_external>", line 724, in exec_module
  File "<frozen importlib._bootstrap_external>", line 860, in get_code
  File "<frozen importlib._bootstrap_external>", line 791, in source_to_code
  File "<frozen importlib._bootstrap>", line 219, in _call_with_frames_removed
  File "/opt/airflow/dags/process_users_dag.py", line 42
    [get_users_from_csv(), _get_users_from_postgress]
                                                      ^
IndentationError: unindent does not match any outer indentation level
[2022-06-03 16:17:19,857] {processor.py:653} WARNING - No viable dags retrieved from /opt/airflow/dags/process_users_dag.py
[2022-06-03 16:17:19,890] {processor.py:161} INFO - Processing /opt/airflow/dags/process_users_dag.py took 0.040 seconds
[2022-06-03 16:17:49,977] {processor.py:153} INFO - Started process (PID=4012) to work on /opt/airflow/dags/process_users_dag.py
[2022-06-03 16:17:49,983] {processor.py:641} INFO - Processing file /opt/airflow/dags/process_users_dag.py for tasks to queue
[2022-06-03 16:17:49,984] {logging_mixin.py:115} INFO - [2022-06-03 16:17:49,984] {dagbag.py:507} INFO - Filling up the DagBag from /opt/airflow/dags/process_users_dag.py
[2022-06-03 16:17:49,987] {logging_mixin.py:115} INFO - [2022-06-03 16:17:49,986] {dagbag.py:320} ERROR - Failed to import: /opt/airflow/dags/process_users_dag.py
Traceback (most recent call last):
  File "/home/airflow/.local/lib/python3.7/site-packages/airflow/models/dagbag.py", line 317, in parse
    loader.exec_module(new_module)
  File "<frozen importlib._bootstrap_external>", line 724, in exec_module
  File "<frozen importlib._bootstrap_external>", line 860, in get_code
  File "<frozen importlib._bootstrap_external>", line 791, in source_to_code
  File "<frozen importlib._bootstrap>", line 219, in _call_with_frames_removed
  File "/opt/airflow/dags/process_users_dag.py", line 42
    [get_users_from_csv(), _get_users_from_postgress]
                                                      ^
IndentationError: unindent does not match any outer indentation level
[2022-06-03 16:17:49,987] {processor.py:653} WARNING - No viable dags retrieved from /opt/airflow/dags/process_users_dag.py
[2022-06-03 16:17:50,015] {processor.py:161} INFO - Processing /opt/airflow/dags/process_users_dag.py took 0.045 seconds
[2022-06-03 16:18:20,095] {processor.py:153} INFO - Started process (PID=4039) to work on /opt/airflow/dags/process_users_dag.py
[2022-06-03 16:18:20,095] {processor.py:641} INFO - Processing file /opt/airflow/dags/process_users_dag.py for tasks to queue
[2022-06-03 16:18:20,096] {logging_mixin.py:115} INFO - [2022-06-03 16:18:20,096] {dagbag.py:507} INFO - Filling up the DagBag from /opt/airflow/dags/process_users_dag.py
[2022-06-03 16:18:20,099] {logging_mixin.py:115} INFO - [2022-06-03 16:18:20,098] {dagbag.py:320} ERROR - Failed to import: /opt/airflow/dags/process_users_dag.py
Traceback (most recent call last):
  File "/home/airflow/.local/lib/python3.7/site-packages/airflow/models/dagbag.py", line 317, in parse
    loader.exec_module(new_module)
  File "<frozen importlib._bootstrap_external>", line 724, in exec_module
  File "<frozen importlib._bootstrap_external>", line 860, in get_code
  File "<frozen importlib._bootstrap_external>", line 791, in source_to_code
  File "<frozen importlib._bootstrap>", line 219, in _call_with_frames_removed
  File "/opt/airflow/dags/process_users_dag.py", line 42
    [get_users_from_csv(), _get_users_from_postgress]
                                                      ^
IndentationError: unindent does not match any outer indentation level
[2022-06-03 16:18:20,099] {processor.py:653} WARNING - No viable dags retrieved from /opt/airflow/dags/process_users_dag.py
[2022-06-03 16:18:20,128] {processor.py:161} INFO - Processing /opt/airflow/dags/process_users_dag.py took 0.037 seconds
[2022-06-03 16:18:50,206] {processor.py:153} INFO - Started process (PID=4059) to work on /opt/airflow/dags/process_users_dag.py
[2022-06-03 16:18:50,213] {processor.py:641} INFO - Processing file /opt/airflow/dags/process_users_dag.py for tasks to queue
[2022-06-03 16:18:50,215] {logging_mixin.py:115} INFO - [2022-06-03 16:18:50,214] {dagbag.py:507} INFO - Filling up the DagBag from /opt/airflow/dags/process_users_dag.py
[2022-06-03 16:18:50,221] {logging_mixin.py:115} INFO - [2022-06-03 16:18:50,219] {dagbag.py:320} ERROR - Failed to import: /opt/airflow/dags/process_users_dag.py
Traceback (most recent call last):
  File "/home/airflow/.local/lib/python3.7/site-packages/airflow/models/dagbag.py", line 317, in parse
    loader.exec_module(new_module)
  File "<frozen importlib._bootstrap_external>", line 724, in exec_module
  File "<frozen importlib._bootstrap_external>", line 860, in get_code
  File "<frozen importlib._bootstrap_external>", line 791, in source_to_code
  File "<frozen importlib._bootstrap>", line 219, in _call_with_frames_removed
  File "/opt/airflow/dags/process_users_dag.py", line 42
    [get_users_from_csv(), _get_users_from_postgress]
                                                      ^
IndentationError: unindent does not match any outer indentation level
[2022-06-03 16:18:50,222] {processor.py:653} WARNING - No viable dags retrieved from /opt/airflow/dags/process_users_dag.py
[2022-06-03 16:18:50,263] {processor.py:161} INFO - Processing /opt/airflow/dags/process_users_dag.py took 0.060 seconds
[2022-06-03 16:19:20,352] {processor.py:153} INFO - Started process (PID=4087) to work on /opt/airflow/dags/process_users_dag.py
[2022-06-03 16:19:20,353] {processor.py:641} INFO - Processing file /opt/airflow/dags/process_users_dag.py for tasks to queue
[2022-06-03 16:19:20,354] {logging_mixin.py:115} INFO - [2022-06-03 16:19:20,354] {dagbag.py:507} INFO - Filling up the DagBag from /opt/airflow/dags/process_users_dag.py
[2022-06-03 16:19:20,360] {logging_mixin.py:115} INFO - [2022-06-03 16:19:20,358] {dagbag.py:320} ERROR - Failed to import: /opt/airflow/dags/process_users_dag.py
Traceback (most recent call last):
  File "/home/airflow/.local/lib/python3.7/site-packages/airflow/models/dagbag.py", line 317, in parse
    loader.exec_module(new_module)
  File "<frozen importlib._bootstrap_external>", line 724, in exec_module
  File "<frozen importlib._bootstrap_external>", line 860, in get_code
  File "<frozen importlib._bootstrap_external>", line 791, in source_to_code
  File "<frozen importlib._bootstrap>", line 219, in _call_with_frames_removed
  File "/opt/airflow/dags/process_users_dag.py", line 42
    [get_users_from_csv(), _get_users_from_postgress]
                                                      ^
IndentationError: unindent does not match any outer indentation level
[2022-06-03 16:19:20,360] {processor.py:653} WARNING - No viable dags retrieved from /opt/airflow/dags/process_users_dag.py
[2022-06-03 16:19:20,418] {processor.py:161} INFO - Processing /opt/airflow/dags/process_users_dag.py took 0.075 seconds
[2022-06-03 16:19:50,498] {processor.py:153} INFO - Started process (PID=4106) to work on /opt/airflow/dags/process_users_dag.py
[2022-06-03 16:19:50,505] {processor.py:641} INFO - Processing file /opt/airflow/dags/process_users_dag.py for tasks to queue
[2022-06-03 16:19:50,505] {logging_mixin.py:115} INFO - [2022-06-03 16:19:50,505] {dagbag.py:507} INFO - Filling up the DagBag from /opt/airflow/dags/process_users_dag.py
[2022-06-03 16:19:50,507] {logging_mixin.py:115} INFO - [2022-06-03 16:19:50,507] {dagbag.py:320} ERROR - Failed to import: /opt/airflow/dags/process_users_dag.py
Traceback (most recent call last):
  File "/home/airflow/.local/lib/python3.7/site-packages/airflow/models/dagbag.py", line 317, in parse
    loader.exec_module(new_module)
  File "<frozen importlib._bootstrap_external>", line 724, in exec_module
  File "<frozen importlib._bootstrap_external>", line 860, in get_code
  File "<frozen importlib._bootstrap_external>", line 791, in source_to_code
  File "<frozen importlib._bootstrap>", line 219, in _call_with_frames_removed
  File "/opt/airflow/dags/process_users_dag.py", line 42
    [get_users_from_csv(), _get_users_from_postgress]
                                                      ^
IndentationError: unindent does not match any outer indentation level
[2022-06-03 16:19:50,508] {processor.py:653} WARNING - No viable dags retrieved from /opt/airflow/dags/process_users_dag.py
[2022-06-03 16:19:50,533] {processor.py:161} INFO - Processing /opt/airflow/dags/process_users_dag.py took 0.038 seconds
[2022-06-03 16:20:20,609] {processor.py:153} INFO - Started process (PID=4134) to work on /opt/airflow/dags/process_users_dag.py
[2022-06-03 16:20:20,609] {processor.py:641} INFO - Processing file /opt/airflow/dags/process_users_dag.py for tasks to queue
[2022-06-03 16:20:20,610] {logging_mixin.py:115} INFO - [2022-06-03 16:20:20,610] {dagbag.py:507} INFO - Filling up the DagBag from /opt/airflow/dags/process_users_dag.py
[2022-06-03 16:20:20,612] {logging_mixin.py:115} INFO - [2022-06-03 16:20:20,611] {dagbag.py:320} ERROR - Failed to import: /opt/airflow/dags/process_users_dag.py
Traceback (most recent call last):
  File "/home/airflow/.local/lib/python3.7/site-packages/airflow/models/dagbag.py", line 317, in parse
    loader.exec_module(new_module)
  File "<frozen importlib._bootstrap_external>", line 724, in exec_module
  File "<frozen importlib._bootstrap_external>", line 860, in get_code
  File "<frozen importlib._bootstrap_external>", line 791, in source_to_code
  File "<frozen importlib._bootstrap>", line 219, in _call_with_frames_removed
  File "/opt/airflow/dags/process_users_dag.py", line 42
    [get_users_from_csv(), _get_users_from_postgress]
                                                      ^
IndentationError: unindent does not match any outer indentation level
[2022-06-03 16:20:20,612] {processor.py:653} WARNING - No viable dags retrieved from /opt/airflow/dags/process_users_dag.py
[2022-06-03 16:20:20,641] {processor.py:161} INFO - Processing /opt/airflow/dags/process_users_dag.py took 0.036 seconds
[2022-06-03 16:20:50,759] {processor.py:153} INFO - Started process (PID=4154) to work on /opt/airflow/dags/process_users_dag.py
[2022-06-03 16:20:50,768] {processor.py:641} INFO - Processing file /opt/airflow/dags/process_users_dag.py for tasks to queue
[2022-06-03 16:20:50,771] {logging_mixin.py:115} INFO - [2022-06-03 16:20:50,771] {dagbag.py:507} INFO - Filling up the DagBag from /opt/airflow/dags/process_users_dag.py
[2022-06-03 16:20:50,780] {logging_mixin.py:115} INFO - [2022-06-03 16:20:50,777] {dagbag.py:320} ERROR - Failed to import: /opt/airflow/dags/process_users_dag.py
Traceback (most recent call last):
  File "/home/airflow/.local/lib/python3.7/site-packages/airflow/models/dagbag.py", line 317, in parse
    loader.exec_module(new_module)
  File "<frozen importlib._bootstrap_external>", line 724, in exec_module
  File "<frozen importlib._bootstrap_external>", line 860, in get_code
  File "<frozen importlib._bootstrap_external>", line 791, in source_to_code
  File "<frozen importlib._bootstrap>", line 219, in _call_with_frames_removed
  File "/opt/airflow/dags/process_users_dag.py", line 42
    [get_users_from_csv(), _get_users_from_postgress]
                                                      ^
IndentationError: unindent does not match any outer indentation level
[2022-06-03 16:20:50,782] {processor.py:653} WARNING - No viable dags retrieved from /opt/airflow/dags/process_users_dag.py
[2022-06-03 16:20:50,819] {processor.py:161} INFO - Processing /opt/airflow/dags/process_users_dag.py took 0.076 seconds
[2022-06-03 16:21:20,918] {processor.py:153} INFO - Started process (PID=4174) to work on /opt/airflow/dags/process_users_dag.py
[2022-06-03 16:21:20,920] {processor.py:641} INFO - Processing file /opt/airflow/dags/process_users_dag.py for tasks to queue
[2022-06-03 16:21:20,923] {logging_mixin.py:115} INFO - [2022-06-03 16:21:20,923] {dagbag.py:507} INFO - Filling up the DagBag from /opt/airflow/dags/process_users_dag.py
[2022-06-03 16:21:20,930] {logging_mixin.py:115} INFO - [2022-06-03 16:21:20,928] {dagbag.py:320} ERROR - Failed to import: /opt/airflow/dags/process_users_dag.py
Traceback (most recent call last):
  File "/home/airflow/.local/lib/python3.7/site-packages/airflow/models/dagbag.py", line 317, in parse
    loader.exec_module(new_module)
  File "<frozen importlib._bootstrap_external>", line 724, in exec_module
  File "<frozen importlib._bootstrap_external>", line 860, in get_code
  File "<frozen importlib._bootstrap_external>", line 791, in source_to_code
  File "<frozen importlib._bootstrap>", line 219, in _call_with_frames_removed
  File "/opt/airflow/dags/process_users_dag.py", line 42
    [get_users_from_csv(), _get_users_from_postgress]
                                                      ^
IndentationError: unindent does not match any outer indentation level
[2022-06-03 16:21:20,931] {processor.py:653} WARNING - No viable dags retrieved from /opt/airflow/dags/process_users_dag.py
[2022-06-03 16:21:20,992] {processor.py:161} INFO - Processing /opt/airflow/dags/process_users_dag.py took 0.088 seconds
[2022-06-03 16:21:51,093] {processor.py:153} INFO - Started process (PID=4202) to work on /opt/airflow/dags/process_users_dag.py
[2022-06-03 16:21:51,101] {processor.py:641} INFO - Processing file /opt/airflow/dags/process_users_dag.py for tasks to queue
[2022-06-03 16:21:51,103] {logging_mixin.py:115} INFO - [2022-06-03 16:21:51,102] {dagbag.py:507} INFO - Filling up the DagBag from /opt/airflow/dags/process_users_dag.py
[2022-06-03 16:21:51,112] {logging_mixin.py:115} INFO - [2022-06-03 16:21:51,109] {dagbag.py:320} ERROR - Failed to import: /opt/airflow/dags/process_users_dag.py
Traceback (most recent call last):
  File "/home/airflow/.local/lib/python3.7/site-packages/airflow/models/dagbag.py", line 317, in parse
    loader.exec_module(new_module)
  File "<frozen importlib._bootstrap_external>", line 724, in exec_module
  File "<frozen importlib._bootstrap_external>", line 860, in get_code
  File "<frozen importlib._bootstrap_external>", line 791, in source_to_code
  File "<frozen importlib._bootstrap>", line 219, in _call_with_frames_removed
  File "/opt/airflow/dags/process_users_dag.py", line 42
    [get_users_from_csv(), _get_users_from_postgress]
                                                      ^
IndentationError: unindent does not match any outer indentation level
[2022-06-03 16:21:51,113] {processor.py:653} WARNING - No viable dags retrieved from /opt/airflow/dags/process_users_dag.py
[2022-06-03 16:21:51,193] {processor.py:161} INFO - Processing /opt/airflow/dags/process_users_dag.py took 0.111 seconds
[2022-06-03 16:22:21,281] {processor.py:153} INFO - Started process (PID=4222) to work on /opt/airflow/dags/process_users_dag.py
[2022-06-03 16:22:21,282] {processor.py:641} INFO - Processing file /opt/airflow/dags/process_users_dag.py for tasks to queue
[2022-06-03 16:22:21,283] {logging_mixin.py:115} INFO - [2022-06-03 16:22:21,283] {dagbag.py:507} INFO - Filling up the DagBag from /opt/airflow/dags/process_users_dag.py
[2022-06-03 16:22:21,286] {logging_mixin.py:115} INFO - [2022-06-03 16:22:21,285] {dagbag.py:320} ERROR - Failed to import: /opt/airflow/dags/process_users_dag.py
Traceback (most recent call last):
  File "/home/airflow/.local/lib/python3.7/site-packages/airflow/models/dagbag.py", line 317, in parse
    loader.exec_module(new_module)
  File "<frozen importlib._bootstrap_external>", line 724, in exec_module
  File "<frozen importlib._bootstrap_external>", line 860, in get_code
  File "<frozen importlib._bootstrap_external>", line 791, in source_to_code
  File "<frozen importlib._bootstrap>", line 219, in _call_with_frames_removed
  File "/opt/airflow/dags/process_users_dag.py", line 42
    [get_users_from_csv(), _get_users_from_postgress]
                                                      ^
IndentationError: unindent does not match any outer indentation level
[2022-06-03 16:22:21,286] {processor.py:653} WARNING - No viable dags retrieved from /opt/airflow/dags/process_users_dag.py
[2022-06-03 16:22:21,318] {processor.py:161} INFO - Processing /opt/airflow/dags/process_users_dag.py took 0.043 seconds
[2022-06-03 16:22:51,411] {processor.py:153} INFO - Started process (PID=4250) to work on /opt/airflow/dags/process_users_dag.py
[2022-06-03 16:22:51,413] {processor.py:641} INFO - Processing file /opt/airflow/dags/process_users_dag.py for tasks to queue
[2022-06-03 16:22:51,414] {logging_mixin.py:115} INFO - [2022-06-03 16:22:51,414] {dagbag.py:507} INFO - Filling up the DagBag from /opt/airflow/dags/process_users_dag.py
[2022-06-03 16:22:51,418] {logging_mixin.py:115} INFO - [2022-06-03 16:22:51,416] {dagbag.py:320} ERROR - Failed to import: /opt/airflow/dags/process_users_dag.py
Traceback (most recent call last):
  File "/home/airflow/.local/lib/python3.7/site-packages/airflow/models/dagbag.py", line 317, in parse
    loader.exec_module(new_module)
  File "<frozen importlib._bootstrap_external>", line 724, in exec_module
  File "<frozen importlib._bootstrap_external>", line 860, in get_code
  File "<frozen importlib._bootstrap_external>", line 791, in source_to_code
  File "<frozen importlib._bootstrap>", line 219, in _call_with_frames_removed
  File "/opt/airflow/dags/process_users_dag.py", line 42
    [get_users_from_csv(), _get_users_from_postgress]
                                                      ^
IndentationError: unindent does not match any outer indentation level
[2022-06-03 16:22:51,418] {processor.py:653} WARNING - No viable dags retrieved from /opt/airflow/dags/process_users_dag.py
[2022-06-03 16:22:51,453] {processor.py:161} INFO - Processing /opt/airflow/dags/process_users_dag.py took 0.047 seconds
[2022-06-03 16:23:21,526] {processor.py:153} INFO - Started process (PID=4269) to work on /opt/airflow/dags/process_users_dag.py
[2022-06-03 16:23:21,526] {processor.py:641} INFO - Processing file /opt/airflow/dags/process_users_dag.py for tasks to queue
[2022-06-03 16:23:21,527] {logging_mixin.py:115} INFO - [2022-06-03 16:23:21,527] {dagbag.py:507} INFO - Filling up the DagBag from /opt/airflow/dags/process_users_dag.py
[2022-06-03 16:23:21,529] {logging_mixin.py:115} INFO - [2022-06-03 16:23:21,528] {dagbag.py:320} ERROR - Failed to import: /opt/airflow/dags/process_users_dag.py
Traceback (most recent call last):
  File "/home/airflow/.local/lib/python3.7/site-packages/airflow/models/dagbag.py", line 317, in parse
    loader.exec_module(new_module)
  File "<frozen importlib._bootstrap_external>", line 724, in exec_module
  File "<frozen importlib._bootstrap_external>", line 860, in get_code
  File "<frozen importlib._bootstrap_external>", line 791, in source_to_code
  File "<frozen importlib._bootstrap>", line 219, in _call_with_frames_removed
  File "/opt/airflow/dags/process_users_dag.py", line 42
    [get_users_from_csv(), _get_users_from_postgress]
                                                      ^
IndentationError: unindent does not match any outer indentation level
[2022-06-03 16:23:21,529] {processor.py:653} WARNING - No viable dags retrieved from /opt/airflow/dags/process_users_dag.py
[2022-06-03 16:23:21,556] {processor.py:161} INFO - Processing /opt/airflow/dags/process_users_dag.py took 0.034 seconds
[2022-06-03 16:23:51,626] {processor.py:153} INFO - Started process (PID=4289) to work on /opt/airflow/dags/process_users_dag.py
[2022-06-03 16:23:51,633] {processor.py:641} INFO - Processing file /opt/airflow/dags/process_users_dag.py for tasks to queue
[2022-06-03 16:23:51,634] {logging_mixin.py:115} INFO - [2022-06-03 16:23:51,634] {dagbag.py:507} INFO - Filling up the DagBag from /opt/airflow/dags/process_users_dag.py
[2022-06-03 16:23:51,638] {logging_mixin.py:115} INFO - [2022-06-03 16:23:51,637] {dagbag.py:320} ERROR - Failed to import: /opt/airflow/dags/process_users_dag.py
Traceback (most recent call last):
  File "/home/airflow/.local/lib/python3.7/site-packages/airflow/models/dagbag.py", line 317, in parse
    loader.exec_module(new_module)
  File "<frozen importlib._bootstrap_external>", line 724, in exec_module
  File "<frozen importlib._bootstrap_external>", line 860, in get_code
  File "<frozen importlib._bootstrap_external>", line 791, in source_to_code
  File "<frozen importlib._bootstrap>", line 219, in _call_with_frames_removed
  File "/opt/airflow/dags/process_users_dag.py", line 42
    [get_users_from_csv(), _get_users_from_postgress]
                                                      ^
IndentationError: unindent does not match any outer indentation level
[2022-06-03 16:23:51,639] {processor.py:653} WARNING - No viable dags retrieved from /opt/airflow/dags/process_users_dag.py
[2022-06-03 16:23:51,668] {processor.py:161} INFO - Processing /opt/airflow/dags/process_users_dag.py took 0.048 seconds
[2022-06-03 16:24:21,746] {processor.py:153} INFO - Started process (PID=4318) to work on /opt/airflow/dags/process_users_dag.py
[2022-06-03 16:24:21,747] {processor.py:641} INFO - Processing file /opt/airflow/dags/process_users_dag.py for tasks to queue
[2022-06-03 16:24:21,748] {logging_mixin.py:115} INFO - [2022-06-03 16:24:21,748] {dagbag.py:507} INFO - Filling up the DagBag from /opt/airflow/dags/process_users_dag.py
[2022-06-03 16:24:21,752] {logging_mixin.py:115} INFO - [2022-06-03 16:24:21,751] {dagbag.py:320} ERROR - Failed to import: /opt/airflow/dags/process_users_dag.py
Traceback (most recent call last):
  File "/home/airflow/.local/lib/python3.7/site-packages/airflow/models/dagbag.py", line 317, in parse
    loader.exec_module(new_module)
  File "<frozen importlib._bootstrap_external>", line 724, in exec_module
  File "<frozen importlib._bootstrap_external>", line 860, in get_code
  File "<frozen importlib._bootstrap_external>", line 791, in source_to_code
  File "<frozen importlib._bootstrap>", line 219, in _call_with_frames_removed
  File "/opt/airflow/dags/process_users_dag.py", line 42
    [get_users_from_csv(), _get_users_from_postgress]
                                                      ^
IndentationError: unindent does not match any outer indentation level
[2022-06-03 16:24:21,752] {processor.py:653} WARNING - No viable dags retrieved from /opt/airflow/dags/process_users_dag.py
[2022-06-03 16:24:21,795] {processor.py:161} INFO - Processing /opt/airflow/dags/process_users_dag.py took 0.058 seconds
[2022-06-03 16:24:51,874] {processor.py:153} INFO - Started process (PID=4337) to work on /opt/airflow/dags/process_users_dag.py
[2022-06-03 16:24:51,881] {processor.py:641} INFO - Processing file /opt/airflow/dags/process_users_dag.py for tasks to queue
[2022-06-03 16:24:51,882] {logging_mixin.py:115} INFO - [2022-06-03 16:24:51,882] {dagbag.py:507} INFO - Filling up the DagBag from /opt/airflow/dags/process_users_dag.py
[2022-06-03 16:24:51,887] {logging_mixin.py:115} INFO - [2022-06-03 16:24:51,885] {dagbag.py:320} ERROR - Failed to import: /opt/airflow/dags/process_users_dag.py
Traceback (most recent call last):
  File "/home/airflow/.local/lib/python3.7/site-packages/airflow/models/dagbag.py", line 317, in parse
    loader.exec_module(new_module)
  File "<frozen importlib._bootstrap_external>", line 724, in exec_module
  File "<frozen importlib._bootstrap_external>", line 860, in get_code
  File "<frozen importlib._bootstrap_external>", line 791, in source_to_code
  File "<frozen importlib._bootstrap>", line 219, in _call_with_frames_removed
  File "/opt/airflow/dags/process_users_dag.py", line 42
    [get_users_from_csv(), _get_users_from_postgress]
                                                      ^
IndentationError: unindent does not match any outer indentation level
[2022-06-03 16:24:51,888] {processor.py:653} WARNING - No viable dags retrieved from /opt/airflow/dags/process_users_dag.py
[2022-06-03 16:24:51,922] {processor.py:161} INFO - Processing /opt/airflow/dags/process_users_dag.py took 0.054 seconds
[2022-06-03 16:25:21,994] {processor.py:153} INFO - Started process (PID=4357) to work on /opt/airflow/dags/process_users_dag.py
[2022-06-03 16:25:21,994] {processor.py:641} INFO - Processing file /opt/airflow/dags/process_users_dag.py for tasks to queue
[2022-06-03 16:25:21,995] {logging_mixin.py:115} INFO - [2022-06-03 16:25:21,995] {dagbag.py:507} INFO - Filling up the DagBag from /opt/airflow/dags/process_users_dag.py
[2022-06-03 16:25:21,997] {logging_mixin.py:115} INFO - [2022-06-03 16:25:21,997] {dagbag.py:320} ERROR - Failed to import: /opt/airflow/dags/process_users_dag.py
Traceback (most recent call last):
  File "/home/airflow/.local/lib/python3.7/site-packages/airflow/models/dagbag.py", line 317, in parse
    loader.exec_module(new_module)
  File "<frozen importlib._bootstrap_external>", line 724, in exec_module
  File "<frozen importlib._bootstrap_external>", line 860, in get_code
  File "<frozen importlib._bootstrap_external>", line 791, in source_to_code
  File "<frozen importlib._bootstrap>", line 219, in _call_with_frames_removed
  File "/opt/airflow/dags/process_users_dag.py", line 42
    [get_users_from_csv(), _get_users_from_postgress]
                                                      ^
IndentationError: unindent does not match any outer indentation level
[2022-06-03 16:25:21,998] {processor.py:653} WARNING - No viable dags retrieved from /opt/airflow/dags/process_users_dag.py
[2022-06-03 16:25:22,025] {processor.py:161} INFO - Processing /opt/airflow/dags/process_users_dag.py took 0.035 seconds
[2022-06-03 16:25:52,097] {processor.py:153} INFO - Started process (PID=4386) to work on /opt/airflow/dags/process_users_dag.py
[2022-06-03 16:25:52,103] {processor.py:641} INFO - Processing file /opt/airflow/dags/process_users_dag.py for tasks to queue
[2022-06-03 16:25:52,104] {logging_mixin.py:115} INFO - [2022-06-03 16:25:52,104] {dagbag.py:507} INFO - Filling up the DagBag from /opt/airflow/dags/process_users_dag.py
[2022-06-03 16:25:52,107] {logging_mixin.py:115} INFO - [2022-06-03 16:25:52,106] {dagbag.py:320} ERROR - Failed to import: /opt/airflow/dags/process_users_dag.py
Traceback (most recent call last):
  File "/home/airflow/.local/lib/python3.7/site-packages/airflow/models/dagbag.py", line 317, in parse
    loader.exec_module(new_module)
  File "<frozen importlib._bootstrap_external>", line 724, in exec_module
  File "<frozen importlib._bootstrap_external>", line 860, in get_code
  File "<frozen importlib._bootstrap_external>", line 791, in source_to_code
  File "<frozen importlib._bootstrap>", line 219, in _call_with_frames_removed
  File "/opt/airflow/dags/process_users_dag.py", line 42
    [get_users_from_csv(), _get_users_from_postgress]
                                                      ^
IndentationError: unindent does not match any outer indentation level
[2022-06-03 16:25:52,107] {processor.py:653} WARNING - No viable dags retrieved from /opt/airflow/dags/process_users_dag.py
[2022-06-03 16:25:52,137] {processor.py:161} INFO - Processing /opt/airflow/dags/process_users_dag.py took 0.044 seconds
[2022-06-03 16:26:22,211] {processor.py:153} INFO - Started process (PID=4405) to work on /opt/airflow/dags/process_users_dag.py
[2022-06-03 16:26:22,212] {processor.py:641} INFO - Processing file /opt/airflow/dags/process_users_dag.py for tasks to queue
[2022-06-03 16:26:22,213] {logging_mixin.py:115} INFO - [2022-06-03 16:26:22,213] {dagbag.py:507} INFO - Filling up the DagBag from /opt/airflow/dags/process_users_dag.py
[2022-06-03 16:26:22,216] {logging_mixin.py:115} INFO - [2022-06-03 16:26:22,215] {dagbag.py:320} ERROR - Failed to import: /opt/airflow/dags/process_users_dag.py
Traceback (most recent call last):
  File "/home/airflow/.local/lib/python3.7/site-packages/airflow/models/dagbag.py", line 317, in parse
    loader.exec_module(new_module)
  File "<frozen importlib._bootstrap_external>", line 724, in exec_module
  File "<frozen importlib._bootstrap_external>", line 860, in get_code
  File "<frozen importlib._bootstrap_external>", line 791, in source_to_code
  File "<frozen importlib._bootstrap>", line 219, in _call_with_frames_removed
  File "/opt/airflow/dags/process_users_dag.py", line 42
    [get_users_from_csv(), _get_users_from_postgress]
                                                      ^
IndentationError: unindent does not match any outer indentation level
[2022-06-03 16:26:22,216] {processor.py:653} WARNING - No viable dags retrieved from /opt/airflow/dags/process_users_dag.py
[2022-06-03 16:26:22,246] {processor.py:161} INFO - Processing /opt/airflow/dags/process_users_dag.py took 0.039 seconds
[2022-06-03 16:26:52,297] {processor.py:153} INFO - Started process (PID=4433) to work on /opt/airflow/dags/process_users_dag.py
[2022-06-03 16:26:52,304] {processor.py:641} INFO - Processing file /opt/airflow/dags/process_users_dag.py for tasks to queue
[2022-06-03 16:26:52,305] {logging_mixin.py:115} INFO - [2022-06-03 16:26:52,305] {dagbag.py:507} INFO - Filling up the DagBag from /opt/airflow/dags/process_users_dag.py
[2022-06-03 16:26:52,309] {logging_mixin.py:115} INFO - [2022-06-03 16:26:52,307] {dagbag.py:320} ERROR - Failed to import: /opt/airflow/dags/process_users_dag.py
Traceback (most recent call last):
  File "/home/airflow/.local/lib/python3.7/site-packages/airflow/models/dagbag.py", line 317, in parse
    loader.exec_module(new_module)
  File "<frozen importlib._bootstrap_external>", line 724, in exec_module
  File "<frozen importlib._bootstrap_external>", line 860, in get_code
  File "<frozen importlib._bootstrap_external>", line 791, in source_to_code
  File "<frozen importlib._bootstrap>", line 219, in _call_with_frames_removed
  File "/opt/airflow/dags/process_users_dag.py", line 42
    [get_users_from_csv(), _get_users_from_postgress]
                                                      ^
IndentationError: unindent does not match any outer indentation level
[2022-06-03 16:26:52,310] {processor.py:653} WARNING - No viable dags retrieved from /opt/airflow/dags/process_users_dag.py
[2022-06-03 16:26:52,340] {processor.py:161} INFO - Processing /opt/airflow/dags/process_users_dag.py took 0.047 seconds
[2022-06-03 16:27:22,443] {processor.py:153} INFO - Started process (PID=4453) to work on /opt/airflow/dags/process_users_dag.py
[2022-06-03 16:27:22,444] {processor.py:641} INFO - Processing file /opt/airflow/dags/process_users_dag.py for tasks to queue
[2022-06-03 16:27:22,444] {logging_mixin.py:115} INFO - [2022-06-03 16:27:22,444] {dagbag.py:507} INFO - Filling up the DagBag from /opt/airflow/dags/process_users_dag.py
[2022-06-03 16:27:22,447] {logging_mixin.py:115} INFO - [2022-06-03 16:27:22,446] {dagbag.py:320} ERROR - Failed to import: /opt/airflow/dags/process_users_dag.py
Traceback (most recent call last):
  File "/home/airflow/.local/lib/python3.7/site-packages/airflow/models/dagbag.py", line 317, in parse
    loader.exec_module(new_module)
  File "<frozen importlib._bootstrap_external>", line 724, in exec_module
  File "<frozen importlib._bootstrap_external>", line 860, in get_code
  File "<frozen importlib._bootstrap_external>", line 791, in source_to_code
  File "<frozen importlib._bootstrap>", line 219, in _call_with_frames_removed
  File "/opt/airflow/dags/process_users_dag.py", line 42
    [get_users_from_csv(), _get_users_from_postgress]
                                                      ^
IndentationError: unindent does not match any outer indentation level
[2022-06-03 16:27:22,447] {processor.py:653} WARNING - No viable dags retrieved from /opt/airflow/dags/process_users_dag.py
[2022-06-03 16:27:22,472] {processor.py:161} INFO - Processing /opt/airflow/dags/process_users_dag.py took 0.032 seconds
[2022-06-03 16:27:52,587] {processor.py:153} INFO - Started process (PID=4472) to work on /opt/airflow/dags/process_users_dag.py
[2022-06-03 16:27:52,595] {processor.py:641} INFO - Processing file /opt/airflow/dags/process_users_dag.py for tasks to queue
[2022-06-03 16:27:52,597] {logging_mixin.py:115} INFO - [2022-06-03 16:27:52,596] {dagbag.py:507} INFO - Filling up the DagBag from /opt/airflow/dags/process_users_dag.py
[2022-06-03 16:27:52,604] {logging_mixin.py:115} INFO - [2022-06-03 16:27:52,602] {dagbag.py:320} ERROR - Failed to import: /opt/airflow/dags/process_users_dag.py
Traceback (most recent call last):
  File "/home/airflow/.local/lib/python3.7/site-packages/airflow/models/dagbag.py", line 317, in parse
    loader.exec_module(new_module)
  File "<frozen importlib._bootstrap_external>", line 724, in exec_module
  File "<frozen importlib._bootstrap_external>", line 860, in get_code
  File "<frozen importlib._bootstrap_external>", line 791, in source_to_code
  File "<frozen importlib._bootstrap>", line 219, in _call_with_frames_removed
  File "/opt/airflow/dags/process_users_dag.py", line 42
    [get_users_from_csv(), _get_users_from_postgress]
                                                      ^
IndentationError: unindent does not match any outer indentation level
[2022-06-03 16:27:52,605] {processor.py:653} WARNING - No viable dags retrieved from /opt/airflow/dags/process_users_dag.py
[2022-06-03 16:27:52,674] {processor.py:161} INFO - Processing /opt/airflow/dags/process_users_dag.py took 0.099 seconds
[2022-06-03 16:28:22,770] {processor.py:153} INFO - Started process (PID=4501) to work on /opt/airflow/dags/process_users_dag.py
[2022-06-03 16:28:22,770] {processor.py:641} INFO - Processing file /opt/airflow/dags/process_users_dag.py for tasks to queue
[2022-06-03 16:28:22,771] {logging_mixin.py:115} INFO - [2022-06-03 16:28:22,771] {dagbag.py:507} INFO - Filling up the DagBag from /opt/airflow/dags/process_users_dag.py
[2022-06-03 16:28:22,773] {logging_mixin.py:115} INFO - [2022-06-03 16:28:22,772] {dagbag.py:320} ERROR - Failed to import: /opt/airflow/dags/process_users_dag.py
Traceback (most recent call last):
  File "/home/airflow/.local/lib/python3.7/site-packages/airflow/models/dagbag.py", line 317, in parse
    loader.exec_module(new_module)
  File "<frozen importlib._bootstrap_external>", line 724, in exec_module
  File "<frozen importlib._bootstrap_external>", line 860, in get_code
  File "<frozen importlib._bootstrap_external>", line 791, in source_to_code
  File "<frozen importlib._bootstrap>", line 219, in _call_with_frames_removed
  File "/opt/airflow/dags/process_users_dag.py", line 42
    [get_users_from_csv(), _get_users_from_postgress]
                                                      ^
IndentationError: unindent does not match any outer indentation level
[2022-06-03 16:28:22,773] {processor.py:653} WARNING - No viable dags retrieved from /opt/airflow/dags/process_users_dag.py
[2022-06-03 16:28:22,799] {processor.py:161} INFO - Processing /opt/airflow/dags/process_users_dag.py took 0.033 seconds
[2022-06-03 16:28:52,905] {processor.py:153} INFO - Started process (PID=4521) to work on /opt/airflow/dags/process_users_dag.py
[2022-06-03 16:28:52,906] {processor.py:641} INFO - Processing file /opt/airflow/dags/process_users_dag.py for tasks to queue
[2022-06-03 16:28:52,906] {logging_mixin.py:115} INFO - [2022-06-03 16:28:52,906] {dagbag.py:507} INFO - Filling up the DagBag from /opt/airflow/dags/process_users_dag.py
[2022-06-03 16:28:52,908] {logging_mixin.py:115} INFO - [2022-06-03 16:28:52,908] {dagbag.py:320} ERROR - Failed to import: /opt/airflow/dags/process_users_dag.py
Traceback (most recent call last):
  File "/home/airflow/.local/lib/python3.7/site-packages/airflow/models/dagbag.py", line 317, in parse
    loader.exec_module(new_module)
  File "<frozen importlib._bootstrap_external>", line 724, in exec_module
  File "<frozen importlib._bootstrap_external>", line 860, in get_code
  File "<frozen importlib._bootstrap_external>", line 791, in source_to_code
  File "<frozen importlib._bootstrap>", line 219, in _call_with_frames_removed
  File "/opt/airflow/dags/process_users_dag.py", line 42
    [get_users_from_csv(), _get_users_from_postgress]
                                                      ^
IndentationError: unindent does not match any outer indentation level
[2022-06-03 16:28:52,909] {processor.py:653} WARNING - No viable dags retrieved from /opt/airflow/dags/process_users_dag.py
[2022-06-03 16:28:52,932] {processor.py:161} INFO - Processing /opt/airflow/dags/process_users_dag.py took 0.031 seconds
